Workbook

Sheet LDL
D2: CONTRACT / PO | P2: PHÂN LOẠI | T2: THÔNG TIN HÀNG HÓA | AD2: EUR | AE2: 32000 | AJ2: THÔNG TIN VẬN CHUYỂN | BD2: {="Max Lô "&MAX(IFERROR(IF(VALUE(SUBSTITUTE($BD$5:$BD$12797,"Lô ",""))<1000, VALUE(SUBSTITUTE($BD$5:$BD$12797,"Lô ",""))), ""))} -> Max Lô 121 | BH2: PHÍ VẬN CHUYỂN / LÔ | BS2: PHÍ VẬN CHUYỂN / MÃ | BZ2: GIÁ NHẬP KHO | CC2: =SUBTOTAL(9,$CF$960:$CF$1832) -> 2.4678681e+10 | CD2: =SUBTOTAL(9,$BZ$960:$BZ$1832) -> 2.5425752e+10 | CF2: =CD2-CC2 -> 7.4707159e+08 | CG2: =SUBTOTAL(9,BX960:BX1832) -> 6.8183813e+08 | CH2: =CG2/CC2 -> 0.02762863
U3: =SUBTOTAL(9,U5:U96855) -> 61959.42 | AB3: =SUBTOTAL(9,AB5:AB96855) -> 2702174.7 | AC3: =SUBTOTAL(9,AC5:AC96855) -> 2729429.1 | AD3: USD | AE3: 27000 | BD3: {="Max Lô "&MAX(IFERROR(IF(VALUE(SUBSTITUTE($BD$5:$BD$12797,"Lô ",""))>1000, VALUE(SUBSTITUTE($BD$5:$BD$12797,"Lô ",""))), ""))} -> Max Lô 0 | BF3: Cost 1 | BI3: Cost 2 | BJ3: Cost 3 | BL3: Cost 4 | BN3: Cost 5 | BO3: (+OF) | BX3: =SUBTOTAL(109,BX5:BX12824) -> 2.302903e+09 | BY3: =SUBTOTAL(109,BY5:BY1018144) -> 3.1958355e+10 | BZ3: =SUBTOTAL(109,BZ5:BZ1018144) -> 6.3065272e+10 | CA3: =SUBTOTAL(109,CA5:CA1018144) -> 3.257055e+10
B4: TÌNH TRẠNG | C4: NCC | D4: HỢP ĐỒNG | E4: SỐ PO | F4: NGÀY PO | G4: BRAND | H4: PRE-ORDER/STOCK | I4: SỐ DH | J4: NGÀY KHÁCH ĐẶT HÀNG | K4: NGÀY GIAO HÀNG | L4: PHƯƠNG THỨC THANH TOÁN | M4: PAYMENT TERM | N4: NGÀY THANH TOÁN | O4: CATEGORY | P4: SUB-CATEGORY | Q4: SERIES | R4: MODEL | S4: MÃ MISA | T4: TÊN HÀNG HÓA | U4: SL | V4: NGOẠI TỆ | W4: PRICE LIST | X4: GIÁ TRỊ GROSS | Y4: DISCOUNT | Z4: PRICE ORDER | AA4: F.O.C | AB4: GIÁ TRỊ NET/HỢP ĐỒNG (-FOC) | AC4: GIÁ TRỊ NET/HỢP ĐỒNG | AD4: Tỷ giá cho Đơn giá nhập | AE4: Tỷ giá tờ khai | AF4: Thuế nhập khẩu + thuế CBPG | AG4: Giá trị thuế nhập khẩu | AH4: VAT | AI4: Giá trị VAT | AJ4: SỐ INVOICE | AK4: NGÀY INVOICE | AL4: SỐ BILL | AM4: SỐ CONTS/SEAL | AN4: SL CONT/CBM (20/40) | AO4: PHƯƠNG THỨC VẬN CHUYỂN | AP4: ETD S/O | AQ4: ETD/ATD | AR4: ETA | AS4: POL | AT4: POD | AU4: FWD | AV4: SỐ TỜ KHAI | AW4: NGÀY TỜ KHAI | AX4: NGÀY THÔNG QUAN | AY4: DIỄN GIẢI TỜ KHAI | AZ4: HS CODE | BA4: GHI CHÚ HÀNG HÓA | BB4: KHO | BC4: NGÀY NHẬP KHO | BD4: Số lô | BE4: % Tỷ lệ | BF4: Phí lấy hàng EXW/FCA + OF | BG4: Phí lấy hàng FCA | BH4: OF | AF | BI4: Local charge+PVHN+Lưu kho+ Trucking (Chưa VAT) | BJ4: Insurance fee (Chưa VAT) | BK4: D/O / THỬ NGHIỆM/ CP KHÁC | BL4: Phí CSHT+ Lệ phí HQ VND | BM4: TRUCKING FEE | BN4: CHI PHÍ HẢI QUAN (Chưa VAT) | BO4: Phí thủ tục lấy hàng EXW /mã | BP4: Phí thủ tục lấy hàng FCA /mã | BQ4: OF | AF /mã | BR4: Local charge+PVHN+Lưu kho+ Trucking Chưa VAT | BS4: INS FEE /mã (Chưa VAT) | BT4: D/O / THỬ NGHIỆM/ CP KHÁC / mã | BU4: Phí CSHT /mã | BV4: Trucking /mã | BW4: Khai hải quan /mã | BX4: TOTAL COST Vận chuyển | BY4: Giá nhập kho (chưa VAT) | BZ4: Giá trị nhập kho (theo SL) | CA4: Giá vốn max theo mã misa | CB4: Giá bán lẻ | CC4: Giá bán ck | CD4: LN net | CE4: Biên lãi gộp | CF4: Giá trị net vnd
B5: Done | C5: LOUIS POULSEN | D5: SC-LPS-03-091023- DH-0001464&1471&1379 | E5: =D5 -> SC-LPS-03-091023- DH-0001464&1471&1379 | F5: 45208 | G5: Louis Poulsen | H5: PRE-ORDER | I5: DH-0001464&1471&1379 | J5: 27/10/2023 | K5: 16/12/2023 | L5: 100% BEFORE PICK UP | M5: EXW | O5: DECOR LIGHTING | P5: pendant | Q5: PH 5 Ø500mm Pendant | R5: 5741099980 | S5: LPLLP00049 | T5: Đèn Thả PH 5, kích thước: phi 500 x H267 mm, Bằng Aluminum, Màu Đồng Brass (không kèm bóng), hiệu: Louis Poulsen, mã hàng: 5741099980, mới 100% | U5: 2 | V5: EUR | X5: =W5*U5 -> 0 | Z5: 620 | AB5: =IF(AA5="F.O.C", 0, Z5*U5) -> 1240 | AC5: =Z5*U5 -> 1240 | AE5: 25700.56 | AF5: 0 | AG5: =(AC5*AE5+BO5+BP5+BQ5+BS5)*AF5 -> 0 | AI5: =(AC5*AE5+AG5+BF5+BG5+BH5+BJ5)*AH5 -> 0 | AJ5: 1019010048 | AK5: 27/11/2023 | AO5: AIR | AQ5: 10/12/2023 | AV5: 105951072360 | AW5: 45272 | AX5: 12/12/2023 | BA5: Xong | BB5: BÌNH PHÚ | BC5: 45274 | BD5: Lô 1 | BE5: {=IF(BD5="","",AC5/SUMPRODUCT(--(BD5=$BD$4:$BD$12824),$AC$4:$AC$12824))} -> 0.58907363 | BI5: 11951100 | BN5: 600000 | BO5: =VLOOKUP(BD5,$BD$4:$BN$12824,3,0)*BE5 -> 0 | BR5: =VLOOKUP(BD5,$BD$4:$BN$12824,6,0)*BE5 -> 7040077.9 | BS5: =VLOOKUP(BD5,$BD$4:$BN$12824,7,0)*BE5 -> 0 | BU5: =VLOOKUP(BD5,$BD$4:$BN$12824,9,0)*BE5 -> 0 | BW5: =VLOOKUP(BD5,$BD$4:$BN$12824,11,0)*BE5 -> 353444.18 | BX5: =SUM(BO5:BW5) -> 7393522.1 | BY5: =(AB5*AE5+AG5+BX5)/U5 -> 19631108 | BZ5: =BY5*U5 -> 39262216 | CA5: =_xlfn.MAXIFS($BY$4:$BY$12824,$S$4:$S$12824,$S5) -> 19631108 | CF5: =AC5*AE5 -> 31868694
B6: Done | C6: LOUIS POULSEN | D6: SC-LPS-03-091023- DH-0001464&1471&1379 | E6: =D6 -> SC-LPS-03-091023- DH-0001464&1471&1379 | F6: 45208 | G6: Louis Poulsen | H6: PRE-ORDER | I6: DH-0001464&1471&1379 | J6: 27/10/2023 | K6: 16/12/2023 | L6: 100% BEFORE PICK UP | M6: EXW | O6: DECOR LIGHTING | P6: Spare part | Q6: Sparepart | R6: 5744610722 | S6: SPALP00007 | T6: Chụp Đèn PH 4 1/2 - 3 1/2 Top Shade, kích thước : DK 45 cm, bằng thủy tinh, màu trắng, hiệu: Louis Poulsen, mã hàng: 5744610722, mới 100% | U6: 1 | V6: EUR | X6: =W6*U6 -> 0 | Z6: 755 | AB6: =IF(AA6="F.O.C", 0, Z6*U6) -> 755 | AC6: =Z6*U6 -> 755 | AE6: 25700.56 | AF6: 0 | AG6: =(AC6*AE6+BO6+BP6+BQ6+BS6)*AF6 -> 0 | AI6: =(AC6*AE6+AG6+BF6+BG6+BH6+BJ6)*AH6 -> 0 | AJ6: 1019010048 | AK6: 27/11/2023 | AO6: AIR | AQ6: 10/12/2023 | AV6: 105951072360 | AW6: 45272 | AX6: 12/12/2023 | BA6: Xong | BB6: BÌNH PHÚ | BC6: 45274 | BD6: Lô 1 | BE6: {=IF(BD6="","",AC6/SUMPRODUCT(--(BD6=$BD$4:$BD$12824),$AC$4:$AC$12824))} -> 0.35866983 | BO6: =VLOOKUP(BD6,$BD$4:$BN$12824,3,0)*BE6 -> 0 | BR6: =VLOOKUP(BD6,$BD$4:$BN$12824,6,0)*BE6 -> 4286499 | BS6: =VLOOKUP(BD6,$BD$4:$BN$12824,7,0)*BE6 -> 0 | BU6: =VLOOKUP(BD6,$BD$4:$BN$12824,9,0)*BE6 -> 0 | BW6: =VLOOKUP(BD6,$BD$4:$BN$12824,11,0)*BE6 -> 215201.9 | BX6: =SUM(BO6:BW6) -> 4501701 | BY6: =(AB6*AE6+AG6+BX6)/U6 -> 23905624 | BZ6: =BY6*U6 -> 23905624 | CA6: =_xlfn.MAXIFS($BY$4:$BY$12824,$S$4:$S$12824,$S6) -> 23905624 | CF6: =AC6*AE6 -> 19403923
B7: Done | C7: LOUIS POULSEN | D7: SC-LPS-03-091023- DH-0001464&1471&1379 | E7: =D7 -> SC-LPS-03-091023- DH-0001464&1471&1379 | F7: 45208 | G7: Louis Poulsen | H7: PRE-ORDER | I7: DH-0001464&1471&1379 | J7: 27/10/2023 | K7: 16/12/2023 | L7: 100% BEFORE PICK UP | M7: EXW | O7: DECOR LIGHTING | P7: Spare part | Q7: Sparepart | R7: 5741481598 | S7: SPALP00008 | T7: Chụp Đèn PH 3-2 middle shade, kích thước DK 14.4 cm, bằng thủy tinh, màu trắng, hiệu: Louis Poulsen, mã hàng: 5741481598, mới 100% | U7: 1 | V7: EUR | X7: =W7*U7 -> 0 | Z7: 110 | AB7: =IF(AA7="F.O.C", 0, Z7*U7) -> 110 | AC7: =Z7*U7 -> 110 | AE7: 25700.56 | AF7: 0 | AG7: =(AC7*AE7+BO7+BP7+BQ7+BS7)*AF7 -> 0 | AI7: =(AC7*AE7+AG7+BF7+BG7+BH7+BJ7)*AH7 -> 0 | AJ7: 1019010048 | AK7: 27/11/2023 | AO7: AIR | AQ7: 10/12/2023 | AV7: 105951072360 | AW7: 45272 | AX7: 12/12/2023 | BA7: Xong | BB7: BÌNH PHÚ | BC7: 45274 | BD7: Lô 1 | BE7: {=IF(BD7="","",AC7/SUMPRODUCT(--(BD7=$BD$4:$BD$12824),$AC$4:$AC$12824))} -> 0.052256532 | BO7: =VLOOKUP(BD7,$BD$4:$BN$12824,3,0)*BE7 -> 0 | BR7: =VLOOKUP(BD7,$BD$4:$BN$12824,6,0)*BE7 -> 624523.04 | BS7: =VLOOKUP(BD7,$BD$4:$BN$12824,7,0)*BE7 -> 0 | BU7: =VLOOKUP(BD7,$BD$4:$BN$12824,9,0)*BE7 -> 0 | BW7: =VLOOKUP(BD7,$BD$4:$BN$12824,11,0)*BE7 -> 31353.919 | BX7: =SUM(BO7:BW7) -> 655876.96 | BY7: =(AB7*AE7+AG7+BX7)/U7 -> 3482938.6 | BZ7: =BY7*U7 -> 3482938.6 | CA7: =_xlfn.MAXIFS($BY$4:$BY$12824,$S$4:$S$12824,$S7) -> 3482938.6 | CF7: =AC7*AE7 -> 2827061.6
B8: Done | C8: NINE UNITED | D8: SC-NINE UNITED-120923-Ms Thao & Stock | E8: =D8 -> SC-NINE UNITED-120923-Ms Thao & Stock | F8: 45181 | G8: HAY | H8: STOCK | L8: 100% BEFORE PICK UP | M8: EXW | O8: ACCESSORIES | P8: Cushion | R8: AB562-B289-AB30 | S8: SPAHA00017 | T8: Đệm PALISSADE CHAISE LOUNGE QUILTED CUSHION,(D195 xR49.5 xC1)cm,Bằng Mút xốp,Bọc vải Olefin,Màu xám(Sky Grey).Hiệu:HAY.Model:AB562-B289-AB30.Mới 100% | U8: 1 | V8: USD | X8: =W8*U8 -> 0 | Z8: 83.22 | AB8: =IF(AA8="F.O.C", 0, Z8*U8) -> 83.22 | AC8: =Z8*U8 -> 83.22 | AE8: 24090 | AF8: 0 | AG8: =(AC8*AE8+BO8+BP8+BQ8+BS8)*AF8 -> 0 | AI8: =(AC8*AE8+AG8+BF8+BG8+BH8+BJ8)*AH8 -> 0 | AJ8: IN231027082720 | AK8: 45226 | AO8: SEA | AQ8: 23/10/2023 | AV8: 105946807302 | AW8: 45269 | AX8: 09/12/2023 | BA8: Xong | BB8: BÌNH PHÚ | BC8: 45150 | BD8: Lô 2 | BE8: {=IF(BD8="","",AC8/SUMPRODUCT(--(BD8=$BD$4:$BD$12824),$AC$4:$AC$12824))} -> 0.0092820312 | BF8: 21196560 | BI8: 10647120 | BJ8: 450000 | BL8: 500000 | BN8: 1890000 | BO8: =VLOOKUP(BD8,$BD$4:$BN$12824,3,0)*BE8 -> 196747.13 | BR8: =VLOOKUP(BD8,$BD$4:$BN$12824,6,0)*BE8 -> 98826.9 | BS8: =VLOOKUP(BD8,$BD$4:$BN$12824,7,0)*BE8 -> 4176.914 | BU8: =VLOOKUP(BD8,$BD$4:$BN$12824,9,0)*BE8 -> 4641.0156 | BW8: =VLOOKUP(BD8,$BD$4:$BN$12824,11,0)*BE8 -> 17543.039 | BX8: =SUM(BO8:BW8) -> 321935 | BY8: =(AB8*AE8+AG8+BX8)/U8 -> 2326704.8 | BZ8: =BY8*U8 -> 2326704.8 | CA8: =_xlfn.MAXIFS($BY$4:$BY$12824,$S$4:$S$12824,$S8) -> 2945788.5 | CF8: =AC8*AE8 -> 2004769.8
B9: Done | C9: NINE UNITED | D9: SC-NINE UNITED-120923-Ms Thao & Stock | E9: =D9 -> SC-NINE UNITED-120923-Ms Thao & Stock | F9: 45181 | G9: HAY | H9: STOCK | L9: 100% BEFORE PICK UP | M9: EXW | O9: ACCESSORIES | P9: Cushion | R9: AB562-B293-AB30 | S9: SPAHA00016 | T9: Đệm PALISSADE-LOUNGE CHAIR LOW QUILTED CUSHION,(D117xR49.5xC1)cm,Bằng Mút xốp,Bọc vải Olefin,Màu xám(Sky Grey).Hiệu:HAY.Model:AB562-B293-AB30.Mới 100% | U9: 1 | V9: USD | X9: =W9*U9 -> 0 | Z9: 51.87 | AB9: =IF(AA9="F.O.C", 0, Z9*U9) -> 51.87 | AC9: =Z9*U9 -> 51.87 | AE9: 24090 | AF9: 0 | AG9: =(AC9*AE9+BO9+BP9+BQ9+BS9)*AF9 -> 0 | AI9: =(AC9*AE9+AG9+BF9+BG9+BH9+BJ9)*AH9 -> 0 | AJ9: IN231027082720 | AK9: 45226 | AO9: SEA | AQ9: 23/10/2023 | AV9: 105946807302 | AW9: 45269 | AX9: 09/12/2023 | BA9: Xong | BB9: BÌNH PHÚ | BC9: 45150 | BD9: Lô 2 | BE9: {=IF(BD9="","",AC9/SUMPRODUCT(--(BD9=$BD$4:$BD$12824),$AC$4:$AC$12824))} -> 0.0057853756 | BO9: =VLOOKUP(BD9,$BD$4:$BN$12824,3,0)*BE9 -> 122630.06 | BR9: =VLOOKUP(BD9,$BD$4:$BN$12824,6,0)*BE9 -> 61597.588 | BS9: =VLOOKUP(BD9,$BD$4:$BN$12824,7,0)*BE9 -> 2603.419 | BU9: =VLOOKUP(BD9,$BD$4:$BN$12824,9,0)*BE9 -> 2892.6878 | BW9: =VLOOKUP(BD9,$BD$4:$BN$12824,11,0)*BE9 -> 10934.36 | BX9: =SUM(BO9:BW9) -> 200658.12 | BY9: =(AB9*AE9+AG9+BX9)/U9 -> 1450206.4 | BZ9: =BY9*U9 -> 1450206.4 | CA9: =_xlfn.MAXIFS($BY$4:$BY$12824,$S$4:$S$12824,$S9) -> 1450206.4 | CF9: =AC9*AE9 -> 1249548.3
B10: Done | C10: NINE UNITED | D10: SC-NINE UNITED-120923-Ms Thao & Stock | E10: =D10 -> SC-NINE UNITED-120923-Ms Thao & Stock | F10: 45181 | G10: VERPAN | H10: STOCK | L10: 100% BEFORE PICK UP | M10: EXW | O10: FURNITURE | P10: Chairs | R10: V9112018800219 | S10: CLGVP00001 | T10: Ghế EASY CHAIR, DI80 x H84 cm, Bằng Vải Dedar Karandash (004), Màu Vàng.Hiệu:Verpan.Model:V911201 8800219.Mới 100% | U10: 1 | V10: USD | X10: =W10*U10 -> 0 | Z10: 2259.5 | AB10: =IF(AA10="F.O.C", 0, Z10*U10) -> 2259.5 | AC10: =Z10*U10 -> 2259.5 | AE10: 24090 | AF10: 0.25 | AG10: =(AC10*AE10+BO10+BP10+BQ10+BS10)*AF10 -> 14971657 | AI10: =(AC10*AE10+AG10+BF10+BG10+BH10+BJ10)*AH10 -> 0 | AJ10: IN231027082720 | AK10: 45226 | AO10: SEA | AQ10: 23/10/2023 | AV10: 105946807302 | AW10: 45269 | AX10: 09/12/2023 | BA10: Xong | BB10: BÌNH PHÚ | BC10: 45150 | BD10: Lô 2 | BE10: {=IF(BD10="","",AC10/SUMPRODUCT(--(BD10=$BD$4:$BD$12824),$AC$4:$AC$12824))} -> 0.25201574 | BO10: =VLOOKUP(BD10,$BD$4:$BN$12824,3,0)*BE10 -> 5341866.7 | BR10: =VLOOKUP(BD10,$BD$4:$BN$12824,6,0)*BE10 -> 2683241.8 | BS10: =VLOOKUP(BD10,$BD$4:$BN$12824,7,0)*BE10 -> 113407.08 | BU10: =VLOOKUP(BD10,$BD$4:$BN$12824,9,0)*BE10 -> 126007.87 | BW10: =VLOOKUP(BD10,$BD$4:$BN$12824,11,0)*BE10 -> 476309.74 | BX10: =SUM(BO10:BW10) -> 8740833.1 | BY10: =(AB10*AE10+AG10+BX10)/U10 -> 78143845 | BZ10: =BY10*U10 -> 78143845 | CA10: =_xlfn.MAXIFS($BY$4:$BY$12824,$S$4:$S$12824,$S10) -> 78143845 | CF10: =AC10*AE10 -> 54431355
B11: Done | C11: NINE UNITED | D11: SC-NINE UNITED-120923-Ms Thao & Stock | E11: =D11 -> SC-NINE UNITED-120923-Ms Thao & Stock | F11: 45181 | G11: &Tradition | H11: STOCK | L11: 100% BEFORE PICK UP | M11: EXW | O11: FURNITURE | P11: table | R11: 701031 | S11: TBLAT00002 | T11: Bàn trang trí SHUFFLE MH1, mặt bàn tròn, Phi45xH69cm, Bằng Gỗ Lacquered MDF,solid wood, màu quang phổ(spectrum).Hiệu:&Tradition.Model:701031.Mới 100% | U11: 1 | V11: USD | X11: =W11*U11 -> 0 | Z11: 268.4 | AB11: =IF(AA11="F.O.C", 0, Z11*U11) -> 268.4 | AC11: =Z11*U11 -> 268.4 | AE11: 24090 | AF11: 0.05 | AG11: =(AC11*AE11+BO11+BP11+BQ11+BS11)*AF11 -> 355688.67 | AI11: =(AC11*AE11+AG11+BF11+BG11+BH11+BJ11)*AH11 -> 0 | AJ11: IN231027082720 | AK11: 45226 | AO11: SEA | AQ11: 23/10/2023 | AV11: 105946807302 | AW11: 45269 | AX11: 09/12/2023 | BA11: Xong | BB11: BÌNH PHÚ | BC11: 45150 | BD11: Lô 2 | BE11: {=IF(BD11="","",AC11/SUMPRODUCT(--(BD11=$BD$4:$BD$12824),$AC$4:$AC$12824))} -> 0.029936279 | BO11: =VLOOKUP(BD11,$BD$4:$BN$12824,3,0)*BE11 -> 634546.14 | BR11: =VLOOKUP(BD11,$BD$4:$BN$12824,6,0)*BE11 -> 318735.16 | BS11: =VLOOKUP(BD11,$BD$4:$BN$12824,7,0)*BE11 -> 13471.326 | BU11: =VLOOKUP(BD11,$BD$4:$BN$12824,9,0)*BE11 -> 14968.14 | BW11: =VLOOKUP(BD11,$BD$4:$BN$12824,11,0)*BE11 -> 56579.568 | BX11: =SUM(BO11:BW11) -> 1038300.3 | BY11: =(AB11*AE11+AG11+BX11)/U11 -> 7859745 | BZ11: =BY11*U11 -> 7859745 | CA11: =_xlfn.MAXIFS($BY$4:$BY$12824,$S$4:$S$12824,$S11) -> 7859745 | CF11: =AC11*AE11 -> 6465756
B12: Done | C12: NINE UNITED | D12: SC-NINE UNITED-120923-Ms Thao & Stock | E12: =D12 -> SC-NINE UNITED-120923-Ms Thao & Stock | F12: 45181 | G12: &Tradition | H12: STOCK | L12: 100% BEFORE PICK UP | M12: EXW | O12: DECOR LIGHTING | P12: Table lamp | R12: 20712201 | S12: LTLAT00009 | T12: Đèn trang trí FLOWERPOT VP9,công nghệ LED,(Phi 16 x cao 29.5)cm,3W 2700K,bằng PC và thép,màu vàng(Mustard).Hiệu:&Tradition.Model:20712201.Mới 100% | U12: 6 | V12: USD | X12: =W12*U12 -> 0 | Z12: 100.1 | AB12: =IF(AA12="F.O.C", 0, Z12*U12) -> 600.6 | AC12: =Z12*U12 -> 600.6 | AE12: 24090 | AF12: 0 | AG12: =(AC12*AE12+BO12+BP12+BQ12+BS12)*AF12 -> 0 | AI12: =(AC12*AE12+AG12+BF12+BG12+BH12+BJ12)*AH12 -> 0 | AJ12: IN231027082720 | AK12: 45226 | AO12: SEA | AQ12: 23/10/2023 | AV12: 105946807302 | AW12: 45269 | AX12: 09/12/2023 | BA12: Xong | BB12: BÌNH PHÚ | BC12: 45269 | BD12: Lô 2 | BE12: {=IF(BD12="","",AC12/SUMPRODUCT(--(BD12=$BD$4:$BD$12824),$AC$4:$AC$12824))} -> 0.06698856 | BO12: =VLOOKUP(BD12,$BD$4:$BN$12824,3,0)*BE12 -> 1419927 | BR12: =VLOOKUP(BD12,$BD$4:$BN$12824,6,0)*BE12 -> 713235.23 | BS12: =VLOOKUP(BD12,$BD$4:$BN$12824,7,0)*BE12 -> 30144.852 | BU12: =VLOOKUP(BD12,$BD$4:$BN$12824,9,0)*BE12 -> 33494.28 | BW12: =VLOOKUP(BD12,$BD$4:$BN$12824,11,0)*BE12 -> 126608.38 | BX12: =SUM(BO12:BW12) -> 2323409.8 | BY12: =(AB12*AE12+AG12+BX12)/U12 -> 2798644 | BZ12: =BY12*U12 -> 16791864 | CA12: =_xlfn.MAXIFS($BY$4:$BY$12824,$S$4:$S$12824,$S12) -> 4101317.8 | CF12: =AC12*AE12 -> 14468454
B13: Done | C13: NINE UNITED | D13: SC-NINE UNITED-120923-Ms Thao & Stock | E13: =D13 -> SC-NINE UNITED-120923-Ms Thao & Stock | F13: 45181 | G13: &Tradition | H13: STOCK | L13: 100% BEFORE PICK UP | M13: EXW | O13: DECOR LIGHTING | P13: Table lamp | R13: 20713501 | S13: LTLAT00015 | T13: Đèn trang trí FLOWERPOT VP9,công nghệ LED,(Phi 16 x cao 29.5)cm,3W 2700K,bằng PC và thép,Màu hồng(Tangy Pink).Hiệu:&Tradition.Model:20713501.Mới 100% | U13: 2 | V13: USD | X13: =W13*U13 -> 0 | Z13: 100.1 | AB13: =IF(AA13="F.O.C", 0, Z13*U13) -> 200.2 | AC13: =Z13*U13 -> 200.2 | AE13: 24090 | AF13: 0 | AG13: =(AC13*AE13+BO13+BP13+BQ13+BS13)*AF13 -> 0 | AI13: =(AC13*AE13+AG13+BF13+BG13+BH13+BJ13)*AH13 -> 0 | AJ13: IN231027082720 | AK13: 45226 | AO13: SEA | AQ13: 23/10/2023 | AV13: 105946807302 | AW13: 45269 | AX13: 09/12/2023 | BA13: Xong | BB13: BÌNH PHÚ | BC13: 45269 | BD13: Lô 2 | BE13: {=IF(BD13="","",AC13/SUMPRODUCT(--(BD13=$BD$4:$BD$12824),$AC$4:$AC$12824))} -> 0.02232952 | BO13: =VLOOKUP(BD13,$BD$4:$BN$12824,3,0)*BE13 -> 473309.01 | BR13: =VLOOKUP(BD13,$BD$4:$BN$12824,6,0)*BE13 -> 237745.08 | BS13: =VLOOKUP(BD13,$BD$4:$BN$12824,7,0)*BE13 -> 10048.284 | BU13: =VLOOKUP(BD13,$BD$4:$BN$12824,9,0)*BE13 -> 11164.76 | BW13: =VLOOKUP(BD13,$BD$4:$BN$12824,11,0)*BE13 -> 42202.793 | BX13: =SUM(BO13:BW13) -> 774469.92 | BY13: =(AB13*AE13+AG13+BX13)/U13 -> 2798644 | BZ13: =BY13*U13 -> 5597287.9 | CA13: =_xlfn.MAXIFS($BY$4:$BY$12824,$S$4:$S$12824,$S13) -> 2798644 | CF13: =AC13*AE13 -> 4822818
B14: Done | C14: NINE UNITED | D14: SC-NINE UNITED-120923-Ms Thao & Stock | E14: =D14 -> SC-NINE UNITED-120923-Ms Thao & Stock | F14: 45181 | G14: &Tradition | H14: STOCK | L14: 100% BEFORE PICK UP | M14: EXW | O14: DECOR LIGHTING | P14: Table lamp | R14: 20713601 | S14: LTLAT00014 | T14: Đèn trang trí FLOWERPOT VP9,công nghệ LED,(Phi 16 x cao 29.5)cm,3W 2700K,bằng PC và thép,Màu đỏ (Dark Plum).Hiệu:&Tradition.Model:20713601.Mới 100% | U14: 2 | V14: USD | X14: =W14*U14 -> 0 | Z14: 100.1 | AB14: =IF(AA14="F.O.C", 0, Z14*U14) -> 200.2 | AC14: =Z14*U14 -> 200.2 | AE14: 24090 | AF14: 0 | AG14: =(AC14*AE14+BO14+BP14+BQ14+BS14)*AF14 -> 0 | AI14: =(AC14*AE14+AG14+BF14+BG14+BH14+BJ14)*AH14 -> 0 | AJ14: IN231027082720 | AK14: 45226 | AO14: SEA | AQ14: 23/10/2023 | AV14: 105946807302 | AW14: 45269 | AX14: 09/12/2023 | BA14: Xong | BB14: BÌNH PHÚ | BC14: 45269 | BD14: Lô 2 | BE14: {=IF(BD14="","",AC14/SUMPRODUCT(--(BD14=$BD$4:$BD$12824),$AC$4:$AC$12824))} -> 0.02232952 | BO14: =VLOOKUP(BD14,$BD$4:$BN$12824,3,0)*BE14 -> 473309.01 | BR14: =VLOOKUP(BD14,$BD$4:$BN$12824,6,0)*BE14 -> 237745.08 | BS14: =VLOOKUP(BD14,$BD$4:$BN$12824,7,0)*BE14 -> 10048.284 | BU14: =VLOOKUP(BD14,$BD$4:$BN$12824,9,0)*BE14 -> 11164.76 | BW14: =VLOOKUP(BD14,$BD$4:$BN$12824,11,0)*BE14 -> 42202.793 | BX14: =SUM(BO14:BW14) -> 774469.92 | BY14: =(AB14*AE14+AG14+BX14)/U14 -> 2798644 | BZ14: =BY14*U14 -> 5597287.9 | CA14: =_xlfn.MAXIFS($BY$4:$BY$12824,$S$4:$S$12824,$S14) -> 2798644 | CF14: =AC14*AE14 -> 4822818
B15: Done | C15: NINE UNITED | D15: SC-NINE UNITED-120923-Ms Thao & Stock | E15: =D15 -> SC-NINE UNITED-120923-Ms Thao & Stock | F15: 45181 | G15: &Tradition | H15: STOCK | L15: 100% BEFORE PICK UP | M15: EXW | O15: DECOR LIGHTING | P15: Table lamp | R15: 20718901 | S15: LTLAT00002 | T15: Đèn trang trí FLOWERPOT VP9,công nghệ LED,(Phi 16 x cao 29.5)cm,3W 2700K,bằng PC và thép,Màu be (Grey Beige).Hiệu:&Tradition.Model:20718901.Mới 100% | U15: 2 | V15: USD | X15: =W15*U15 -> 0 | Z15: 100.1 | AB15: =IF(AA15="F.O.C", 0, Z15*U15) -> 200.2 | AC15: =Z15*U15 -> 200.2 | AE15: 24090 | AF15: 0 | AG15: =(AC15*AE15+BO15+BP15+BQ15+BS15)*AF15 -> 0 | AI15: =(AC15*AE15+AG15+BF15+BG15+BH15+BJ15)*AH15 -> 0 | AJ15: IN231027082720 | AK15: 45226 | AO15: SEA | AQ15: 23/10/2023 | AV15: 105946807302 | AW15: 45269 | AX15: 09/12/2023 | BA15: Xong | BB15: BÌNH PHÚ | BC15: 45269 | BD15: Lô 2 | BE15: {=IF(BD15="","",AC15/SUMPRODUCT(--(BD15=$BD$4:$BD$12824),$AC$4:$AC$12824))} -> 0.02232952 | BO15: =VLOOKUP(BD15,$BD$4:$BN$12824,3,0)*BE15 -> 473309.01 | BR15: =VLOOKUP(BD15,$BD$4:$BN$12824,6,0)*BE15 -> 237745.08 | BS15: =VLOOKUP(BD15,$BD$4:$BN$12824,7,0)*BE15 -> 10048.284 | BU15: =VLOOKUP(BD15,$BD$4:$BN$12824,9,0)*BE15 -> 11164.76 | BW15: =VLOOKUP(BD15,$BD$4:$BN$12824,11,0)*BE15 -> 42202.793 | BX15: =SUM(BO15:BW15) -> 774469.92 | BY15: =(AB15*AE15+AG15+BX15)/U15 -> 2798644 | BZ15: =BY15*U15 -> 5597287.9 | CA15: =_xlfn.MAXIFS($BY$4:$BY$12824,$S$4:$S$12824,$S15) -> 4101317.8 | CF15: =AC15*AE15 -> 4822818
B16: Done | C16: NINE UNITED | D16: SC-NINE UNITED-120923-Ms Thao & Stock | E16: =D16 -> SC-NINE UNITED-120923-Ms Thao & Stock | F16: 45181 | G16: &Tradition | H16: STOCK | L16: 100% BEFORE PICK UP | M16: EXW | O16: DECOR LIGHTING | P16: Table lamp | R16: 20719201 | S16: LTLAT00001 | T16: Đèn trang trí FLOWERPOT VP9,công nghệ LED,(Phi 16 x cao 29.5)cm,3W 2700K,bằng PC và thép,Màu Lục(Signal Green).Hiệu:&Tradition.Model:20719201.Mới 100% | U16: 6 | V16: USD | X16: =W16*U16 -> 0 | Z16: 100.1 | AB16: =IF(AA16="F.O.C", 0, Z16*U16) -> 600.6 | AC16: =Z16*U16 -> 600.6 | AE16: 24090 | AF16: 0 | AG16: =(AC16*AE16+BO16+BP16+BQ16+BS16)*AF16 -> 0 | AI16: =(AC16*AE16+AG16+BF16+BG16+BH16+BJ16)*AH16 -> 0 | AJ16: IN231027082720 | AK16: 45226 | AO16: SEA | AQ16: 23/10/2023 | AV16: 105946807302 | AW16: 45269 | AX16: 09/12/2023 | BA16: Xong | BB16: BÌNH PHÚ | BC16: 45269 | BD16: Lô 2 | BE16: {=IF(BD16="","",AC16/SUMPRODUCT(--(BD16=$BD$4:$BD$12824),$AC$4:$AC$12824))} -> 0.06698856 | BO16: =VLOOKUP(BD16,$BD$4:$BN$12824,3,0)*BE16 -> 1419927 | BR16: =VLOOKUP(BD16,$BD$4:$BN$12824,6,0)*BE16 -> 713235.23 | BS16: =VLOOKUP(BD16,$BD$4:$BN$12824,7,0)*BE16 -> 30144.852 | BU16: =VLOOKUP(BD16,$BD$4:$BN$12824,9,0)*BE16 -> 33494.28 | BW16: =VLOOKUP(BD16,$BD$4:$BN$12824,11,0)*BE16 -> 126608.38 | BX16: =SUM(BO16:BW16) -> 2323409.8 | BY16: =(AB16*AE16+AG16+BX16)/U16 -> 2798644 | BZ16: =BY16*U16 -> 16791864 | CA16: =_xlfn.MAXIFS($BY$4:$BY$12824,$S$4:$S$12824,$S16) -> 4101317.8 | CF16: =AC16*AE16 -> 14468454
B17: Done | C17: NINE UNITED | D17: SC-NINE UNITED-120923-Ms Thao & Stock | E17: =D17 -> SC-NINE UNITED-120923-Ms Thao & Stock | F17: 45181 | G17: &Tradition | H17: STOCK | L17: 100% BEFORE PICK UP | M17: EXW | O17: FURNITURE | P17: table | R17: 86202005 | S17: TBLAT00003 | T17: Bàn LATO, LN8, Phi 40 x H50 cm, Mặt Bàn tròn bằng kim loại màu trắng Ivory White , Bệ Đá Crema Diva Marble.Hiệu:&Tradition.Model:86202005, 1SET= 1 MẶT BÀN+ 1 CHÂN BÀN.Mới 100% | U17: 1 | V17: USD | X17: =W17*U17 -> 0 | Z17: 251.9 | AB17: =IF(AA17="F.O.C", 0, Z17*U17) -> 251.9 | AC17: =Z17*U17 -> 251.9 | AE17: 24090 | AF17: 0.05 | AG17: =(AC17*AE17+BO17+BP17+BQ17+BS17)*AF17 -> 333822.57 | AI17: =(AC17*AE17+AG17+BF17+BG17+BH17+BJ17)*AH17 -> 0 | AJ17: IN231027082720 | AK17: 45226 | AO17: SEA | AQ17: 23/10/2023 | AV17: 105946807302 | AW17: 45269 | AX17: 09/12/2023 | BA17: Xong | BB17: BÌNH PHÚ | BC17: 45150 | BD17: Lô 2 | BE17: {=IF(BD17="","",AC17/SUMPRODUCT(--(BD17=$BD$4:$BD$12824),$AC$4:$AC$12824))} -> 0.028095934 | BO17: =VLOOKUP(BD17,$BD$4:$BN$12824,3,0)*BE17 -> 595537.16 | BR17: =VLOOKUP(BD17,$BD$4:$BN$12824,6,0)*BE17 -> 299140.79 | BS17: =VLOOKUP(BD17,$BD$4:$BN$12824,7,0)*BE17 -> 12643.17 | BU17: =VLOOKUP(BD17,$BD$4:$BN$12824,9,0)*BE17 -> 14047.967 | BW17: =VLOOKUP(BD17,$BD$4:$BN$12824,11,0)*BE17 -> 53101.316 | BX17: =SUM(BO17:BW17) -> 974470.4 | BY17: =(AB17*AE17+AG17+BX17)/U17 -> 7376564 | BZ17: =BY17*U17 -> 7376564 | CA17: =_xlfn.MAXIFS($BY$4:$BY$12824,$S$4:$S$12824,$S17) -> 7376564 | CF17: =AC17*AE17 -> 6068271
B18: Done | C18: NINE UNITED | D18: SC-NINE UNITED-120923-Ms Thao & Stock | E18: =D18 -> SC-NINE UNITED-120923-Ms Thao & Stock | F18: 45181 | G18: &Tradition | H18: STOCK | L18: 100% BEFORE PICK UP | M18: EXW | O18: FURNITURE | P18: table | R18: 86202015 | S18: TBLAT00004 | T18: Bàn LATO, LN9, L50 x W40 x H45 cm, Mặt Bàn bằng kim loại màu trắng Ivory White , Bệ Đá Crema Diva Marble.Hiệu:&Tradition.Model:86202015 .1SET= 1 MẶT BÀN+ 1 CHÂN BÀN.Mới 100% | U18: 1 | V18: USD | X18: =W18*U18 -> 0 | Z18: 251.9 | AB18: =IF(AA18="F.O.C", 0, Z18*U18) -> 251.9 | AC18: =Z18*U18 -> 251.9 | AE18: 24090 | AF18: 0.05 | AG18: =(AC18*AE18+BO18+BP18+BQ18+BS18)*AF18 -> 333822.57 | AI18: =(AC18*AE18+AG18+BF18+BG18+BH18+BJ18)*AH18 -> 0 | AJ18: IN231027082720 | AK18: 45226 | AO18: SEA | AQ18: 23/10/2023 | AV18: 105946807302 | AW18: 45269 | AX18: 09/12/2023 | BA18: Xong | BB18: BÌNH PHÚ | BC18: 45150 | BD18: Lô 2 | BE18: {=IF(BD18="","",AC18/SUMPRODUCT(--(BD18=$BD$4:$BD$12824),$AC$4:$AC$12824))} -> 0.028095934 | BO18: =VLOOKUP(BD18,$BD$4:$BN$12824,3,0)*BE18 -> 595537.16 | BR18: =VLOOKUP(BD18,$BD$4:$BN$12824,6,0)*BE18 -> 299140.79 | BS18: =VLOOKUP(BD18,$BD$4:$BN$12824,7,0)*BE18 -> 12643.17 | BU18: =VLOOKUP(BD18,$BD$4:$BN$12824,9,0)*BE18 -> 14047.967 | BW18: =VLOOKUP(BD18,$BD$4:$BN$12824,11,0)*BE18 -> 53101.316 | BX18: =SUM(BO18:BW18) -> 974470.4 | BY18: =(AB18*AE18+AG18+BX18)/U18 -> 7376564 | BZ18: =BY18*U18 -> 7376564 | CA18: =_xlfn.MAXIFS($BY$4:$BY$12824,$S$4:$S$12824,$S18) -> 7376564 | CF18: =AC18*AE18 -> 6068271
B19: Done | C19: NINE UNITED | D19: SC-NINE UNITED-120923-Ms Thao & Stock | E19: =D19 -> SC-NINE UNITED-120923-Ms Thao & Stock | F19: 45181 | G19: HAY | H19: STOCK | L19: 100% BEFORE PICK UP | M19: EXW | O19: ACCESSORIES | P19: Vase | R19: 508041 | S19: ACCHA00236 | T19: Bình Hoa Bottoms Up Vase S, H21 x W11 x L11 cm, Bằng thủy tinh, Màu xanh Electric Blue.Hiệu:HAY.Model:508041.Mới 100% | U19: 4 | V19: USD | X19: =W19*U19 -> 0 | Z19: 31.6 | AB19: =IF(AA19="F.O.C", 0, Z19*U19) -> 126.4 | AC19: =Z19*U19 -> 126.4 | AE19: 24090 | AF19: 0.15 | AG19: =(AC19*AE19+BO19+BP19+BQ19+BS19)*AF19 -> 502522.89 | AI19: =(AC19*AE19+AG19+BF19+BG19+BH19+BJ19)*AH19 -> 0 | AJ19: IN231027082720 | AK19: 45226 | AO19: SEA | AQ19: 23/10/2023 | AV19: 105946807302 | AW19: 45269 | AX19: 09/12/2023 | BA19: Xong | BB19: BÌNH PHÚ | BC19: 45150 | BD19: Lô 2 | BE19: {=IF(BD19="","",AC19/SUMPRODUCT(--(BD19=$BD$4:$BD$12824),$AC$4:$AC$12824))} -> 0.014098158 | BO19: =VLOOKUP(BD19,$BD$4:$BN$12824,3,0)*BE19 -> 298832.46 | BR19: =VLOOKUP(BD19,$BD$4:$BN$12824,6,0)*BE19 -> 150104.78 | BS19: =VLOOKUP(BD19,$BD$4:$BN$12824,7,0)*BE19 -> 6344.1713 | BU19: =VLOOKUP(BD19,$BD$4:$BN$12824,9,0)*BE19 -> 7049.0792 | BW19: =VLOOKUP(BD19,$BD$4:$BN$12824,11,0)*BE19 -> 26645.519 | BX19: =SUM(BO19:BW19) -> 488976.02 | BY19: =(AB19*AE19+AG19+BX19)/U19 -> 1009118.7 | BZ19: =BY19*U19 -> 4036474.9 | CA19: =_xlfn.MAXIFS($BY$4:$BY$12824,$S$4:$S$12824,$S19) -> 1009118.7 | CF19: =AC19*AE19 -> 3044976
B20: Done | C20: NINE UNITED | D20: SC-NINE UNITED-120923-Ms Thao & Stock | E20: =D20 -> SC-NINE UNITED-120923-Ms Thao & Stock | F20: 45181 | G20: HAY | H20: STOCK | L20: 100% BEFORE PICK UP | M20: EXW | O20: ACCESSORIES | P20: Organizer | R20: 541441 | S20: ACCHA00227 | T20: Hộp Đa Năng COLOUR CRATE, Cỡ S, L26.5 x W17 x H10.5 cm, Bằngnhựa recycled PP, Màu xanh Dusty blue.Hiệu:HAY.Model:541441.Mới 100% | U20: 24 | V20: USD | X20: =W20*U20 -> 0 | Z20: 2.4 | AB20: =IF(AA20="F.O.C", 0, Z20*U20) -> 57.6 | AC20: =Z20*U20 -> 57.6 | AE20: 24090 | AF20: 0 | AG20: =(AC20*AE20+BO20+BP20+BQ20+BS20)*AF20 -> 0 | AI20: =(AC20*AE20+AG20+BF20+BG20+BH20+BJ20)*AH20 -> 0 | AJ20: IN231027082720 | AK20: 45226 | AO20: SEA | AQ20: 23/10/2023 | AV20: 105946807302 | AW20: 45269 | AX20: 09/12/2023 | BA20: Xong | BB20: BÌNH PHÚ | BC20: 45150 | BD20: Lô 2 | BE20: {=IF(BD20="","",AC20/SUMPRODUCT(--(BD20=$BD$4:$BD$12824),$AC$4:$AC$12824))} -> 0.0064244773 | BO20: =VLOOKUP(BD20,$BD$4:$BN$12824,3,0)*BE20 -> 136176.82 | BR20: =VLOOKUP(BD20,$BD$4:$BN$12824,6,0)*BE20 -> 68402.18 | BS20: =VLOOKUP(BD20,$BD$4:$BN$12824,7,0)*BE20 -> 2891.0148 | BU20: =VLOOKUP(BD20,$BD$4:$BN$12824,9,0)*BE20 -> 3212.2386 | BW20: =VLOOKUP(BD20,$BD$4:$BN$12824,11,0)*BE20 -> 12142.262 | BX20: =SUM(BO20:BW20) -> 222824.51 | BY20: =(AB20*AE20+AG20+BX20)/U20 -> 67100.355 | BZ20: =BY20*U20 -> 1610408.5 | CA20: =_xlfn.MAXIFS($BY$4:$BY$12824,$S$4:$S$12824,$S20) -> 67100.355 | CF20: =AC20*AE20 -> 1387584
... B38: Done | C38: NINE UNITED | D38: SC-NINE UNITED-120923-Ms Thao & Stock | E38: =D38 -> SC-NINE UNITED-120923-Ms Thao & Stock | F38: 45181 | G38: HAY | H38: STOCK | L38: 100% BEFORE PICK UP | M38: EXW | O38: ACCESSORIES | P38: Organizer | R38: 542170 | S38: ACCHA00222 | T38: Hộp Đa Năng COLOUR CRATE, Cỡ M, L40 x W30 x H14.5 cm, Bằng nhựa recycled PP, Màu hỗn hợp Mix Powder.Hiệu:HAY.Model:542170.Mới 100% | U38: 12 | V38: USD | X38: =W38*U38 -> 0 | Z38: 6 | AB38: =IF(AA38="F.O.C", 0, Z38*U38) -> 72 | AC38: =Z38*U38 -> 72 | AE38: 24090 | AF38: 0 | AG38: =(AC38*AE38+BO38+BP38+BQ38+BS38)*AF38 -> 0 | AI38: =(AC38*AE38+AG38+BF38+BG38+BH38+BJ38)*AH38 -> 0 | AJ38: IN231027082720 | AK38: 45226 | AO38: SEA | AQ38: 23/10/2023 | AV38: 105946807302 | AW38: 45269 | AX38: 09/12/2023 | BA38: Xong | BB38: BÌNH PHÚ | BC38: 45150 | BD38: Lô 2 | BE38: {=IF(BD38="","",AC38/SUMPRODUCT(--(BD38=$BD$4:$BD$12824),$AC$4:$AC$12824))} -> 0.0080305966 | BO38: =VLOOKUP(BD38,$BD$4:$BN$12824,3,0)*BE38 -> 170221.02 | BR38: =VLOOKUP(BD38,$BD$4:$BN$12824,6,0)*BE38 -> 85502.725 | BS38: =VLOOKUP(BD38,$BD$4:$BN$12824,7,0)*BE38 -> 3613.7685 | BU38: =VLOOKUP(BD38,$BD$4:$BN$12824,9,0)*BE38 -> 4015.2983 | BW38: =VLOOKUP(BD38,$BD$4:$BN$12824,11,0)*BE38 -> 15177.828 | BX38: =SUM(BO38:BW38) -> 278530.64 | BY38: =(AB38*AE38+AG38+BX38)/U38 -> 167750.89 | BZ38: =BY38*U38 -> 2013010.6 | CA38: =_xlfn.MAXIFS($BY$4:$BY$12824,$S$4:$S$12824,$S38) -> 167750.89 | CF38: =AC38*AE38 -> 1734480
B39: Done | C39: NINE UNITED | D39: SC-Nine United-271023- DH-00014531303 | E39: =D39 -> SC-Nine United-271023- DH-00014531303 | F39: 45226 | G39: HAY | H39: PRE-ORDER | I39: DH-0001453 | J39: 24/10/2023 | K39: 20/12/2023 | L39: 100% BEFORE PICK UP | M39: EXW | O39: FURNITURE | P39: Chairs | R39: AA610-A237 | S39: OUTHA00013 | T39: Ghế PALISSADE BENCH, Kích thước (Dài 120 x Rộng 42 x Cao 45) cm, Bằng Thép, Màu lục (OLIVE).Hiệu:HAY.Model:AA610-A237.Mới 100% | U39: 16 | V39: USD | X39: =W39*U39 -> 0 | Z39: 148.77 | AB39: =IF(AA39="F.O.C", 0, Z39*U39) -> 2380.32 | AC39: =Z39*U39 -> 2380.32 | AE39: 24090 | AF39: 0 | AG39: =(AC39*AE39+BO39+BP39+BQ39+BS39)*AF39 -> 0 | AI39: =(AC39*AE39+AG39+BF39+BG39+BH39+BJ39)*AH39 -> 0 | AJ39: IN231027082720 | AK39: 45226 | AO39: SEA | AQ39: 23/10/2023 | AV39: 105946807302 | AW39: 45269 | AX39: 09/12/2023 | BA39: Xong | BB39: BÌNH PHÚ | BC39: 45150 | BD39: Lô 2 | BE39: {=IF(BD39="","",AC39/SUMPRODUCT(--(BD39=$BD$4:$BD$12824),$AC$4:$AC$12824))} -> 0.26549152 | BO39: =VLOOKUP(BD39,$BD$4:$BN$12824,3,0)*BE39 -> 5627507 | BR39: =VLOOKUP(BD39,$BD$4:$BN$12824,6,0)*BE39 -> 2826720.1 | BS39: =VLOOKUP(BD39,$BD$4:$BN$12824,7,0)*BE39 -> 119471.19 | BU39: =VLOOKUP(BD39,$BD$4:$BN$12824,9,0)*BE39 -> 132745.76 | BW39: =VLOOKUP(BD39,$BD$4:$BN$12824,11,0)*BE39 -> 501778.98 | BX39: =SUM(BO39:BW39) -> 9208223 | BY39: =(AB39*AE39+AG39+BX39)/U39 -> 4159383.2 | BZ39: =BY39*U39 -> 66550132 | CA39: =_xlfn.MAXIFS($BY$4:$BY$12824,$S$4:$S$12824,$S39) -> 4159383.2 | CF39: =AC39*AE39 -> 57341909
B40: Done | C40: NINE UNITED | D40: SC-Nine United-271023- DH-00014531303 | E40: =D40 -> SC-Nine United-271023- DH-00014531303 | F40: 45226 | G40: &Tradition | H40: PRE-ORDER | I40: DH-0001453 | J40: 24/10/2023 | K40: 20/12/2023 | L40: 100% BEFORE PICK UP | M40: EXW | O40: DECOR LIGHTING | P40: pendant | R40: 200600 | S40: LPLAT00004 | T40: Đèn thả Mega Bulb SR2, DI18 x H23cm, Bằng Thủy tinh, Sứ, màu Vàng, dây nhựa Trong suốt (không kèm bóng).Hiệu:&Tradition.Model:200600.Mới 100% | U40: 2 | V40: USD | X40: =W40*U40 -> 0 | Z40: 92.4 | AB40: =IF(AA40="F.O.C", 0, Z40*U40) -> 184.8 | AC40: =Z40*U40 -> 184.8 | AE40: 24090 | AF40: 0 | AG40: =(AC40*AE40+BO40+BP40+BQ40+BS40)*AF40 -> 0 | AI40: =(AC40*AE40+AG40+BF40+BG40+BH40+BJ40)*AH40 -> 0 | AJ40: IN231027082720 | AK40: 45226 | AO40: SEA | AQ40: 23/10/2023 | AV40: 105946807302 | AW40: 45269 | AX40: 09/12/2023 | BA40: Xong | BB40: BÌNH PHÚ | BC40: 45150 | BD40: Lô 2 | BE40: {=IF(BD40="","",AC40/SUMPRODUCT(--(BD40=$BD$4:$BD$12824),$AC$4:$AC$12824))} -> 0.020611865 | BO40: =VLOOKUP(BD40,$BD$4:$BN$12824,3,0)*BE40 -> 436900.62 | BR40: =VLOOKUP(BD40,$BD$4:$BN$12824,6,0)*BE40 -> 219457 | BS40: =VLOOKUP(BD40,$BD$4:$BN$12824,7,0)*BE40 -> 9275.339 | BU40: =VLOOKUP(BD40,$BD$4:$BN$12824,9,0)*BE40 -> 10305.932 | BW40: =VLOOKUP(BD40,$BD$4:$BN$12824,11,0)*BE40 -> 38956.424 | BX40: =SUM(BO40:BW40) -> 714895.31 | BY40: =(AB40*AE40+AG40+BX40)/U40 -> 2583363.7 | BZ40: =BY40*U40 -> 5166727.3 | CA40: =_xlfn.MAXIFS($BY$4:$BY$12824,$S$4:$S$12824,$S40) -> 2583363.7 | CF40: =AC40*AE40 -> 4451832
B41: Done | C41: FLOS | D41: SC-FLOS-110923-STOCK&MR HIEN | E41: =D41 -> SC-FLOS-110923-STOCK&MR HIEN | F41: 45180 | G41: FLOS | H41: STOCK | L41: 100% BEFORE PICK UP | M41: EXW | O41: DECOR LIGHTING | P41: pendant | R41: F9800009 | S41: LPLFL00046 | T41: Đèn Trang Trí ZEPPELIN 1, Phi 1100 x H740 mm, không kèm bóng, màu trắng, hiệu: FLOS. Model: F9800009. mới 100%. | U41: 2 | V41: EUR | X41: =W41*U41 -> 0 | Z41: 1893.65 | AB41: =IF(AA41="F.O.C", 0, Z41*U41) -> 3787.3 | AC41: =Z41*U41 -> 3787.3 | AE41: 26199.57 | AF41: 0 | AG41: =(AC41*AE41+BO41+BP41+BQ41+BS41)*AF41 -> 0 | AI41: =(AC41*AE41+AG41+BF41+BG41+BH41+BJ41)*AH41 -> 0 | AJ41: 2303002821 | AK41: 45203 | AO41: SEA | AQ41: 23/10/2023 | AV41: 105938436551 | AW41: 45266 | AX41: 06/12/2023 | BA41: Xong | BB41: BÌNH PHÚ | BC41: 45150 | BD41: Lô 3 | BE41: {=IF(BD41="","",AC41/SUMPRODUCT(--(BD41=$BD$4:$BD$12824),$AC$4:$AC$12824))} -> 0.38016894 | BF41: 7649033 | BI41: 5093772 | BN41: 600000 | BO41: =VLOOKUP(BD41,$BD$4:$BN$12824,3,0)*BE41 -> 2907924.8 | BR41: =VLOOKUP(BD41,$BD$4:$BN$12824,6,0)*BE41 -> 1936493.9 | BS41: =VLOOKUP(BD41,$BD$4:$BN$12824,7,0)*BE41 -> 0 | BU41: =VLOOKUP(BD41,$BD$4:$BN$12824,9,0)*BE41 -> 0 | BW41: =VLOOKUP(BD41,$BD$4:$BN$12824,11,0)*BE41 -> 228101.36 | BX41: =SUM(BO41:BW41) -> 5072520 | BY41: =(AB41*AE41+AG41+BX41)/U41 -> 52149076 | BZ41: =BY41*U41 -> 1.0429815e+08 | CA41: =_xlfn.MAXIFS($BY$4:$BY$12824,$S$4:$S$12824,$S41) -> 52511523 | CF41: =AC41*AE41 -> 99225631
B42: Done | C42: FLOS | D42: SC-FLOS-110923-STOCK&MR HIEN | E42: =D42 -> SC-FLOS-110923-STOCK&MR HIEN | F42: 45180 | G42: FLOS | H42: STOCK | L42: 100% BEFORE PICK UP | M42: EXW | O42: DECOR LIGHTING | P42: pendant | R42: F8001009 | S42: LPLFL00045 | T42: Đèn trang trí Viscontea, Phi 68 cm x H49 cm, không kèm bóng, bằng thép, cocoon, màu trắng. Hiệu: FLOS. Model: F8001009. mới 100%. | U42: 4 | V42: EUR | X42: =W42*U42 -> 0 | Z42: 811.25 | AB42: =IF(AA42="F.O.C", 0, Z42*U42) -> 3245 | AC42: =Z42*U42 -> 3245 | AE42: 26199.57 | AF42: 0 | AG42: =(AC42*AE42+BO42+BP42+BQ42+BS42)*AF42 -> 0 | AI42: =(AC42*AE42+AG42+BF42+BG42+BH42+BJ42)*AH42 -> 0 | AJ42: 2303002821 | AK42: 45203 | AO42: SEA | AQ42: 23/10/2023 | AV42: 105938436551 | AW42: 45266 | AX42: 06/12/2023 | BA42: Xong | BB42: BÌNH PHÚ | BC42: 45150 | BD42: Lô 3 | BE42: {=IF(BD42="","",AC42/SUMPRODUCT(--(BD42=$BD$4:$BD$12824),$AC$4:$AC$12824))} -> 0.3257329 | BO42: =VLOOKUP(BD42,$BD$4:$BN$12824,3,0)*BE42 -> 2491541.7 | BR42: =VLOOKUP(BD42,$BD$4:$BN$12824,6,0)*BE42 -> 1659209.1 | BS42: =VLOOKUP(BD42,$BD$4:$BN$12824,7,0)*BE42 -> 0 | BU42: =VLOOKUP(BD42,$BD$4:$BN$12824,9,0)*BE42 -> 0 | BW42: =VLOOKUP(BD42,$BD$4:$BN$12824,11,0)*BE42 -> 195439.74 | BX42: =SUM(BO42:BW42) -> 4346190.6 | BY42: =(AB42*AE42+AG42+BX42)/U42 -> 22340949 | BZ42: =BY42*U42 -> 89363795 | CA42: =_xlfn.MAXIFS($BY$4:$BY$12824,$S$4:$S$12824,$S42) -> 22340949 | CF42: =AC42*AE42 -> 85017605
B43: Done | C43: FLOS | D43: SC-FLOS-110923-STOCK&MR HIEN | E43: =D43 -> SC-FLOS-110923-STOCK&MR HIEN | F43: 45180 | G43: FLOS | H43: STOCK | L43: 100% BEFORE PICK UP | M43: EXW | O43: DECOR LIGHTING | P43: pendant | R43: F7402009 | S43: LPLFL00051 | T43: Đèn Thả TARAXACUM S2, phi 870 x H640 mm, Không kèm bóng, Khung Kim Loại, Cocoon, Màu Trắng Bianco White.Hiệu: FLOS, Model: F7402009, mới 100%. | U43: 1 | V43: EUR | X43: =W43*U43 -> 0 | Z43: 1036.75 | AB43: =IF(AA43="F.O.C", 0, Z43*U43) -> 1036.75 | AC43: =Z43*U43 -> 1036.75 | AE43: 26199.57 | AF43: 0 | AG43: =(AC43*AE43+BO43+BP43+BQ43+BS43)*AF43 -> 0 | AI43: =(AC43*AE43+AG43+BF43+BG43+BH43+BJ43)*AH43 -> 0 | AJ43: 2303002821 | AK43: 45203 | AO43: SEA | AQ43: 23/10/2023 | AV43: 105938436551 | AW43: 45266 | AX43: 06/12/2023 | BA43: Xong | BB43: BÌNH PHÚ | BC43: 45150 | BD43: Lô 3 | BE43: {=IF(BD43="","",AC43/SUMPRODUCT(--(BD43=$BD$4:$BD$12824),$AC$4:$AC$12824))} -> 0.1040689 | BO43: =VLOOKUP(BD43,$BD$4:$BN$12824,3,0)*BE43 -> 796026.46 | BR43: =VLOOKUP(BD43,$BD$4:$BN$12824,6,0)*BE43 -> 530103.25 | BS43: =VLOOKUP(BD43,$BD$4:$BN$12824,7,0)*BE43 -> 0 | BU43: =VLOOKUP(BD43,$BD$4:$BN$12824,9,0)*BE43 -> 0 | BW43: =VLOOKUP(BD43,$BD$4:$BN$12824,11,0)*BE43 -> 62441.34 | BX43: =SUM(BO43:BW43) -> 1388571 | BY43: =(AB43*AE43+AG43+BX43)/U43 -> 28550975 | BZ43: =BY43*U43 -> 28550975 | CA43: =_xlfn.MAXIFS($BY$4:$BY$12824,$S$4:$S$12824,$S43) -> 29844310 | CF43: =AC43*AE43 -> 27162404
B44: Done | C44: FLOS | D44: SC-FLOS-110923-STOCK&MR HIEN | E44: =D44 -> SC-FLOS-110923-STOCK&MR HIEN | F44: 45180 | G44: FLOS | H44: STOCK | L44: 100% BEFORE PICK UP | M44: EXW | O44: DECOR LIGHTING | P44: Floor lamp | R44: F1590056 | S44: LFLFL00025 | T44: Đèn Sàn CHIARA F, Phi 720 x L1450 mm, Không kèm bóng, Bằng Thép Stainless, Màu Trắng Viền Đen.Hiệu: FLOS, Model: F1590056, mới 100% | U44: 2 | V44: EUR | X44: =W44*U44 -> 0 | Z44: 946.55 | AB44: =IF(AA44="F.O.C", 0, Z44*U44) -> 1893.1 | AC44: =Z44*U44 -> 1893.1 | AE44: 26199.57 | AF44: 0 | AG44: =(AC44*AE44+BO44+BP44+BQ44+BS44)*AF44 -> 0 | AI44: =(AC44*AE44+AG44+BF44+BG44+BH44+BJ44)*AH44 -> 0 | AJ44: 2303002821 | AK44: 45203 | AO44: SEA | AQ44: 23/10/2023 | AV44: 105938436551 | AW44: 45266 | AX44: 06/12/2023 | BA44: Xong | BB44: BÌNH PHÚ | BC44: 45150 | BD44: Lô 3 | BE44: {=IF(BD44="","",AC44/SUMPRODUCT(--(BD44=$BD$4:$BD$12824),$AC$4:$AC$12824))} -> 0.19002926 | BO44: =VLOOKUP(BD44,$BD$4:$BN$12824,3,0)*BE44 -> 1453540.1 | BR44: =VLOOKUP(BD44,$BD$4:$BN$12824,6,0)*BE44 -> 967965.73 | BS44: =VLOOKUP(BD44,$BD$4:$BN$12824,7,0)*BE44 -> 0 | BU44: =VLOOKUP(BD44,$BD$4:$BN$12824,9,0)*BE44 -> 0 | BW44: =VLOOKUP(BD44,$BD$4:$BN$12824,11,0)*BE44 -> 114017.56 | BX44: =SUM(BO44:BW44) -> 2535523.4 | BY44: =(AB44*AE44+AG44+BX44)/U44 -> 26066965 | BZ44: =BY44*U44 -> 52133929 | CA44: =_xlfn.MAXIFS($BY$4:$BY$12824,$S$4:$S$12824,$S44) -> 26066965 | CF44: =AC44*AE44 -> 49598406
B45: Done | C45: USM | D45: SC-USM-15-220823-A TAI&CAMPAIGN | E45: =D45 -> SC-USM-15-220823-A TAI&CAMPAIGN | F45: 45160 | G45: USM | H45: STOCK | L45: 100% BEFORE PICK UP | M45: FCA | O45: FURNITURE | P45: Cabinet | R45: USMUS00368 | S45: USMUS00368 | T45: Tủ nội thất văn phòng USM HALLER, USMUS00368, Kích thước (dài 773 x rộng 373 x cao 1090 mm), Bằng Kim loại, Màu Olive. Hiệu USM | U45: 1 | V45: EUR | X45: =W45*U45 -> 0 | Z45: 746.2 | AB45: =IF(AA45="F.O.C", 0, Z45*U45) -> 746.2 | AC45: =Z45*U45 -> 746.2 | AE45: 25889.59 | AF45: 0.1 | AG45: =(AC45*AE45+BO45+BP45+BQ45+BS45)*AF45 -> 2499664.6 | AI45: =(AC45*AE45+AG45+BF45+BG45+BH45+BJ45)*AH45 -> 0 | AJ45: 102083254 | AK45: 45244 | AO45: AIR | AQ45: 17/11/2023 | AV45: 105902755340 | AW45: 45252 | AX45: 22/11/2023 | BA45: Xong | BB45: BÌNH PHÚ | BC45: 45253 | BD45: Lô 4 | BE45: {=IF(BD45="","",AC45/SUMPRODUCT(--(BD45=$BD$4:$BD$12824),$AC$4:$AC$12824))} -> 0.28697572 | BF45: 19785068 | BI45: =(486480+851340+ 467360) -> 1805180 | BN45: 600000 | BO45: =VLOOKUP(BD45,$BD$4:$BN$12824,3,0)*BE45 -> 5677834.1 | BR45: =VLOOKUP(BD45,$BD$4:$BN$12824,6,0)*BE45 -> 518042.83 | BS45: =VLOOKUP(BD45,$BD$4:$BN$12824,7,0)*BE45 -> 0 | BU45: =VLOOKUP(BD45,$BD$4:$BN$12824,9,0)*BE45 -> 0 | BW45: =VLOOKUP(BD45,$BD$4:$BN$12824,11,0)*BE45 -> 172185.43 | BX45: =SUM(BO45:BW45) -> 6368062.3 | BY45: =(AB45*AE45+AG45+BX45)/U45 -> 28186539 | BZ45: =BY45*U45 -> 28186539 | CA45: =_xlfn.MAXIFS($BY$4:$BY$12824,$S$4:$S$12824,$S45) -> 28186539 | CF45: =AC45*AE45 -> 19318812
B46: Done | C46: USM | D46: SC-USM-15-220823-A TAI&CAMPAIGN | E46: =D46 -> SC-USM-15-220823-A TAI&CAMPAIGN | F46: 45160 | G46: USM | H46: STOCK | L46: 100% BEFORE PICK UP | M46: FCA | O46: FURNITURE | P46: Cabinet | R46: USMUS00367 | S46: USMUS00367 | T46: Tủ nội thất văn phòng USM HALLER, USMUS00367, Kích thước (dài 1523 x rộng 373 x cao 740 mm), Bằng Kim loại, Màu Olive. Hiệu USM | U46: 1 | V46: EUR | X46: =W46*U46 -> 0 | Z46: 946.75 | AB46: =IF(AA46="F.O.C", 0, Z46*U46) -> 946.75 | AC46: =Z46*U46 -> 946.75 | AE46: 25889.59 | AF46: 0.1 | AG46: =(AC46*AE46+BO46+BP46+BQ46+BS46)*AF46 -> 3171478.8 | AI46: =(AC46*AE46+AG46+BF46+BG46+BH46+BJ46)*AH46 -> 0 | AJ46: 102083254 | AK46: 45244 | AO46: AIR | AQ46: 17/11/2023 | AV46: 105902755340 | AW46: 45252 | AX46: 22/11/2023 | BA46: Xong | BB46: BÌNH PHÚ | BC46: 45253 | BD46: Lô 4 | BE46: {=IF(BD46="","",AC46/SUMPRODUCT(--(BD46=$BD$4:$BD$12824),$AC$4:$AC$12824))} -> 0.36410381 | BO46: =VLOOKUP(BD46,$BD$4:$BN$12824,3,0)*BE46 -> 7203818.6 | BR46: =VLOOKUP(BD46,$BD$4:$BN$12824,6,0)*BE46 -> 657272.91 | BS46: =VLOOKUP(BD46,$BD$4:$BN$12824,7,0)*BE46 -> 0 | BU46: =VLOOKUP(BD46,$BD$4:$BN$12824,9,0)*BE46 -> 0 | BW46: =VLOOKUP(BD46,$BD$4:$BN$12824,11,0)*BE46 -> 218462.28 | BX46: =SUM(BO46:BW46) -> 8079553.8 | BY46: =(AB46*AE46+AG46+BX46)/U46 -> 35762002 | BZ46: =BY46*U46 -> 35762002 | CA46: =_xlfn.MAXIFS($BY$4:$BY$12824,$S$4:$S$12824,$S46) -> 35762002 | CF46: =AC46*AE46 -> 24510969
B47: Done | C47: USM | D47: SC-USM-15-220823-A TAI&CAMPAIGN | E47: =D47 -> SC-USM-15-220823-A TAI&CAMPAIGN | F47: 45160 | G47: USM | H47: STOCK | L47: 100% BEFORE PICK UP | M47: FCA | O47: FURNITURE | P47: Cabinet | R47: USMUS00369 | S47: USMUS00369 | T47: Tủ nội thất văn phòng USM HALLER, USMUS00369, Kích thước (dài 1523 x rộng 373 x cao 610 mm), Bằng Kim loại, Màu Olive. Hiệu USM | U47: 1 | V47: EUR | X47: =W47*U47 -> 0 | Z47: 671.66 | AB47: =IF(AA47="F.O.C", 0, Z47*U47) -> 671.66 | AC47: =Z47*U47 -> 671.66 | AE47: 25889.59 | AF47: 0.1 | AG47: =(AC47*AE47+BO47+BP47+BQ47+BS47)*AF47 -> 2249966.1 | AI47: =(AC47*AE47+AG47+BF47+BG47+BH47+BJ47)*AH47 -> 0 | AJ47: 102083254 | AK47: 45244 | AO47: AIR | AQ47: 17/11/2023 | AV47: 105902755340 | AW47: 45252 | AX47: 22/11/2023 | BA47: Xong | BB47: BÌNH PHÚ | BC47: 45253 | BD47: Lô 4 | BE47: {=IF(BD47="","",AC47/SUMPRODUCT(--(BD47=$BD$4:$BD$12824),$AC$4:$AC$12824))} -> 0.25830891 | BO47: =VLOOKUP(BD47,$BD$4:$BN$12824,3,0)*BE47 -> 5110659.4 | BR47: =VLOOKUP(BD47,$BD$4:$BN$12824,6,0)*BE47 -> 466294.08 | BS47: =VLOOKUP(BD47,$BD$4:$BN$12824,7,0)*BE47 -> 0 | BU47: =VLOOKUP(BD47,$BD$4:$BN$12824,9,0)*BE47 -> 0 | BW47: =VLOOKUP(BD47,$BD$4:$BN$12824,11,0)*BE47 -> 154985.35 | BX47: =SUM(BO47:BW47) -> 5731938.8 | BY47: =(AB47*AE47+AG47+BX47)/U47 -> 25370907 | BZ47: =BY47*U47 -> 25370907 | CA47: =_xlfn.MAXIFS($BY$4:$BY$12824,$S$4:$S$12824,$S47) -> 25370907 | CF47: =AC47*AE47 -> 17389002
B48: Done | C48: USM | D48: SC-USM-15-220823-A TAI&CAMPAIGN | E48: =D48 -> SC-USM-15-220823-A TAI&CAMPAIGN | F48: 45160 | G48: USM | H48: STOCK | L48: 100% BEFORE PICK UP | M48: FCA | O48: FURNITURE | P48: Cabinet | R48: USMUS10171 | S48: USMUS10171 | T48: Kệ văn phòng USM HALLER có bánh xe,USMUS10171,Kích thước (D523xR373xC605 mm), Bằng Kim loại, Màu Trắng (Pure White), Cam (Pure Orange). Hiệu USM | U48: 1 | V48: EUR | X48: =W48*U48 -> 0 | Z48: 235.61 | AB48: =IF(AA48="F.O.C", 0, Z48*U48) -> 235.61 | AC48: =Z48*U48 -> 235.61 | AE48: 25889.59 | AF48: 0.1 | AG48: =(AC48*AE48+BO48+BP48+BQ48+BS48)*AF48 -> 789260.22 | AI48: =(AC48*AE48+AG48+BF48+BG48+BH48+BJ48)*AH48 -> 0 | AJ48: 102083254 | AK48: 45244 | AO48: AIR | AQ48: 17/11/2023 | AV48: 105902755340 | AW48: 45252 | AX48: 22/11/2023 | BA48: Xong | BB48: BÌNH PHÚ | BC48: 45253 | BD48: Lô 4 | BE48: {=IF(BD48="","",AC48/SUMPRODUCT(--(BD48=$BD$4:$BD$12824),$AC$4:$AC$12824))} -> 0.090611564 | BO48: =VLOOKUP(BD48,$BD$4:$BN$12824,3,0)*BE48 -> 1792755.9 | BR48: =VLOOKUP(BD48,$BD$4:$BN$12824,6,0)*BE48 -> 163570.18 | BS48: =VLOOKUP(BD48,$BD$4:$BN$12824,7,0)*BE48 -> 0 | BU48: =VLOOKUP(BD48,$BD$4:$BN$12824,9,0)*BE48 -> 0 | BW48: =VLOOKUP(BD48,$BD$4:$BN$12824,11,0)*BE48 -> 54366.938 | BX48: =SUM(BO48:BW48) -> 2010693.1 | BY48: =(AB48*AE48+AG48+BX48)/U48 -> 8899799.6 | BZ48: =BY48*U48 -> 8899799.6 | CA48: =_xlfn.MAXIFS($BY$4:$BY$12824,$S$4:$S$12824,$S48) -> 8899799.6 | CF48: =AC48*AE48 -> 6099846.3
B49: Done | C49: USM | D49: SC-USM-290623 | E49: SC-USM-290623 | F49: 45106 | G49: USM | H49: STOCK | L49: 100% BEFORE PICK UP | M49: FCA | O49: FURNITURE | P49: Cabinet | R49: USMUS10007 | S49: USMUS10007 | T49: Tủ nội thất văn phòng USM HALLER, USMUS10007, kích thước (dài 4273 x rộng 1123 x cao 990 mm), bằng Kim loại, màu Vàng (Golden Yellow). Hiệu USM | U49: 1 | V49: EUR | X49: =W49*U49 -> 0 | Z49: 2962.41 | AB49: =IF(AA49="F.O.C", 0, Z49*U49) -> 2962.41 | AC49: =Z49*U49 -> 2962.41 | AE49: 25590.88 | AF49: 0.1 | AG49: =(AC49*AE49+BO49+BP49+BQ49+BS49)*AF49 -> 7794876.3 | AI49: =(AC49*AE49+AG49+BF49+BG49+BH49+BJ49)*AH49 -> 0 | AJ49: 102082282 | AK49: 13/07/2023 | AO49: SEA | AQ49: 03/08/2023 | AV49: 105728943720 | AW49: 45189 | AX49: 20/09/2023 | BA49: Xong | BB49: BÌNH PHÚ | BC49: 45195 | BD49: Lô 5 | BE49: {=IF(BD49="","",AC49/SUMPRODUCT(--(BD49=$BD$4:$BD$12824),$AC$4:$AC$12824))} -> 0.034175753 | BF49: 60393000 | BI49: 4104000 | BJ49: 2168428 | BL49: 500000 | BO49: =VLOOKUP(BD49,$BD$4:$BN$12824,3,0)*BE49 -> 2063976.3 | BR49: =VLOOKUP(BD49,$BD$4:$BN$12824,6,0)*BE49 -> 140257.29 | BS49: =VLOOKUP(BD49,$BD$4:$BN$12824,7,0)*BE49 -> 74107.66 | BU49: =VLOOKUP(BD49,$BD$4:$BN$12824,9,0)*BE49 -> 17087.877 | BW49: =VLOOKUP(BD49,$BD$4:$BN$12824,11,0)*BE49 -> 0 | BX49: =SUM(BO49:BW49) -> 2295429.1 | BY49: =(AB49*AE49+AG49+BX49)/U49 -> 85900984 | BZ49: =BY49*U49 -> 85900984 | CA49: =_xlfn.MAXIFS($BY$4:$BY$12824,$S$4:$S$12824,$S49) -> 85900984 | CF49: =AC49*AE49 -> 75810679
B50: Done | C50: USM | D50: SC-USM-290623 | E50: SC-USM-290623 | F50: 45106 | G50: USM | H50: STOCK | L50: 100% BEFORE PICK UP | M50: FCA | O50: FURNITURE | P50: Cabinet | R50: USMUS10008 | S50: USMUS10008 | T50: Tủ nội thất văn phòng USM HALLER, USMUS10008, kích thước (dài 7019 x rộng 1523 x cao 2490 mm), bằng Kim loại, màu Vàng (Golden Yellow). Hiệu USM | U50: 1 | V50: EUR | X50: =W50*U50 -> 0 | Z50: 7665.29 | AB50: =IF(AA50="F.O.C", 0, Z50*U50) -> 7665.29 | AC50: =Z50*U50 -> 7665.29 | AE50: 25590.88 | AF50: 0.1 | AG50: =(AC50*AE50+BO50+BP50+BQ50+BS50)*AF50 -> 20169385 | AI50: =(AC50*AE50+AG50+BF50+BG50+BH50+BJ50)*AH50 -> 0 | AJ50: 102082282 | AK50: 13/07/2023 | AO50: SEA | AQ50: 03/08/2023 | AV50: 105728943720 | AW50: 45189 | AX50: 20/09/2023 | BA50: Xong | BB50: BÌNH PHÚ | BC50: 45195 | BD50: Lô 5 | BE50: {=IF(BD50="","",AC50/SUMPRODUCT(--(BD50=$BD$4:$BD$12824),$AC$4:$AC$12824))} -> 0.088430386 | BO50: =VLOOKUP(BD50,$BD$4:$BN$12824,3,0)*BE50 -> 5340576.3 | BR50: =VLOOKUP(BD50,$BD$4:$BN$12824,6,0)*BE50 -> 362918.3 | BS50: =VLOOKUP(BD50,$BD$4:$BN$12824,7,0)*BE50 -> 191754.93 | BU50: =VLOOKUP(BD50,$BD$4:$BN$12824,9,0)*BE50 -> 44215.193 | BW50: =VLOOKUP(BD50,$BD$4:$BN$12824,11,0)*BE50 -> 0 | BX50: =SUM(BO50:BW50) -> 5939464.7 | BY50: =(AB50*AE50+AG50+BX50)/U50 -> 2.2227037e+08 | BZ50: =BY50*U50 -> 2.2227037e+08 | CA50: =_xlfn.MAXIFS($BY$4:$BY$12824,$S$4:$S$12824,$S50) -> 2.2227037e+08 | CF50: =AC50*AE50 -> 1.9616152e+08
B51: Done | C51: USM | D51: SC-USM-290623 | E51: SC-USM-290623 | F51: 45106 | G51: USM | H51: STOCK | L51: 100% BEFORE PICK UP | M51: FCA | O51: FURNITURE | P51: Cabinet | R51: USMUS10009 | S51: USMUS10009 | T51: Tủ nội thất văn phòng USM HALLER, USMUS10009, kích thước (dài 4373 x rộng 1873 x cao 2140 mm), bằng Kim loại, màu Trắng (Pure White), màu Vàng (Golden Yellow), màu Đen (Graphite Black). Hiệu USM | U51: 1 | V51: EUR | X51: =W51*U51 -> 0 | Z51: 2935.7 | AB51: =IF(AA51="F.O.C", 0, Z51*U51) -> 2935.7 | AC51: =Z51*U51 -> 2935.7 | AE51: 25590.88 | AF51: 0.1 | AG51: =(AC51*AE51+BO51+BP51+BQ51+BS51)*AF51 -> 7724595.3 | AI51: =(AC51*AE51+AG51+BF51+BG51+BH51+BJ51)*AH51 -> 0 | AJ51: 102082282 | AK51: 13/07/2023 | AO51: SEA | AQ51: 03/08/2023 | AV51: 105728943720 | AW51: 45189 | AX51: 20/09/2023 | BA51: Xong | BB51: BÌNH PHÚ | BC51: 45195 | BD51: Lô 5 | BE51: {=IF(BD51="","",AC51/SUMPRODUCT(--(BD51=$BD$4:$BD$12824),$AC$4:$AC$12824))} -> 0.033867614 | BO51: =VLOOKUP(BD51,$BD$4:$BN$12824,3,0)*BE51 -> 2045366.8 | BR51: =VLOOKUP(BD51,$BD$4:$BN$12824,6,0)*BE51 -> 138992.69 | BS51: =VLOOKUP(BD51,$BD$4:$BN$12824,7,0)*BE51 -> 73439.483 | BU51: =VLOOKUP(BD51,$BD$4:$BN$12824,9,0)*BE51 -> 16933.807 | BW51: =VLOOKUP(BD51,$BD$4:$BN$12824,11,0)*BE51 -> 0 | BX51: =SUM(BO51:BW51) -> 2274732.8 | BY51: =(AB51*AE51+AG51+BX51)/U51 -> 85126474 | BZ51: =BY51*U51 -> 85126474 | CA51: =_xlfn.MAXIFS($BY$4:$BY$12824,$S$4:$S$12824,$S51) -> 85126474 | CF51: =AC51*AE51 -> 75127146
B52: Done | C52: USM | D52: SC-USM-290623 | E52: SC-USM-290623 | F52: 45106 | G52: USM | H52: STOCK | L52: 100% BEFORE PICK UP | M52: FCA | O52: FURNITURE | P52: Cabinet | R52: USMUS10010 | S52: USMUS10010 | T52: Tủ nội thất văn phòng USM HALLER, USMUS10010, kích thước (dài 1523 x rộng 373 x cao 1090 mm), bằng Kim loại, màu Trắng (Pure White), màu Vàng (Golden Yellow), màu Đen (Graphite Black). Hiệu USM | U52: 1 | V52: EUR | X52: =W52*U52 -> 0 | Z52: 849.3 | AB52: =IF(AA52="F.O.C", 0, Z52*U52) -> 849.3 | AC52: =Z52*U52 -> 849.3 | AE52: 25590.88 | AF52: 0.1 | AG52: =(AC52*AE52+BO52+BP52+BQ52+BS52)*AF52 -> 2234730.6 | AI52: =(AC52*AE52+AG52+BF52+BG52+BH52+BJ52)*AH52 -> 0 | AJ52: 102082282 | AK52: 13/07/2023 | AO52: SEA | AQ52: 03/08/2023 | AV52: 105728943720 | AW52: 45189 | AX52: 20/09/2023 | BA52: Xong | BB52: BÌNH PHÚ | BC52: 45195 | BD52: Lô 5 | BE52: {=IF(BD52="","",AC52/SUMPRODUCT(--(BD52=$BD$4:$BD$12824),$AC$4:$AC$12824))} -> 0.0097979237 | BO52: =VLOOKUP(BD52,$BD$4:$BN$12824,3,0)*BE52 -> 591726.01 | BR52: =VLOOKUP(BD52,$BD$4:$BN$12824,6,0)*BE52 -> 40210.679 | BS52: =VLOOKUP(BD52,$BD$4:$BN$12824,7,0)*BE52 -> 21246.092 | BU52: =VLOOKUP(BD52,$BD$4:$BN$12824,9,0)*BE52 -> 4898.9619 | BW52: =VLOOKUP(BD52,$BD$4:$BN$12824,11,0)*BE52 -> 0 | BX52: =SUM(BO52:BW52) -> 658081.74 | BY52: =(AB52*AE52+AG52+BX52)/U52 -> 24627147 | BZ52: =BY52*U52 -> 24627147 | CA52: =_xlfn.MAXIFS($BY$4:$BY$12824,$S$4:$S$12824,$S52) -> 24627147 | CF52: =AC52*AE52 -> 21734334
B53: Done | C53: USM | D53: SC-USM-290623 | E53: SC-USM-290623 | F53: 45106 | G53: USM | H53: STOCK | L53: 100% BEFORE PICK UP | M53: FCA | O53: FURNITURE | P53: Cabinet | R53: USMUS10011 | S53: USMUS10011 | T53: Tủ nội thất văn phòng USM HALLER, USMUS10011, kích thước (dài 2273 x rộng 373 x cao 1090 mm), bằng Kim loại, màu Xám (Anthracite). Hiệu USM | U53: 1 | V53: EUR | X53: =W53*U53 -> 0 | Z53: 826.37 | AB53: =IF(AA53="F.O.C", 0, Z53*U53) -> 826.37 | AC53: =Z53*U53 -> 826.37 | AE53: 25590.88 | AF53: 0.1 | AG53: =(AC53*AE53+BO53+BP53+BQ53+BS53)*AF53 -> 2174395.8 | AI53: =(AC53*AE53+AG53+BF53+BG53+BH53+BJ53)*AH53 -> 0 | AJ53: 102082282 | AK53: 13/07/2023 | AO53: SEA | AQ53: 03/08/2023 | AV53: 105728943720 | AW53: 45189 | AX53: 20/09/2023 | BA53: Xong | BB53: BÌNH PHÚ | BC53: 45195 | BD53: Lô 5 | BE53: {=IF(BD53="","",AC53/SUMPRODUCT(--(BD53=$BD$4:$BD$12824),$AC$4:$AC$12824))} -> 0.0095333925 | BO53: =VLOOKUP(BD53,$BD$4:$BN$12824,3,0)*BE53 -> 575750.17 | BR53: =VLOOKUP(BD53,$BD$4:$BN$12824,6,0)*BE53 -> 39125.043 | BS53: =VLOOKUP(BD53,$BD$4:$BN$12824,7,0)*BE53 -> 20672.475 | BU53: =VLOOKUP(BD53,$BD$4:$BN$12824,9,0)*BE53 -> 4766.6962 | BW53: =VLOOKUP(BD53,$BD$4:$BN$12824,11,0)*BE53 -> 0 | BX53: =SUM(BO53:BW53) -> 640314.39 | BY53: =(AB53*AE53+AG53+BX53)/U53 -> 23962246 | BZ53: =BY53*U53 -> 23962246 | CA53: =_xlfn.MAXIFS($BY$4:$BY$12824,$S$4:$S$12824,$S53) -> 23962246 | CF53: =AC53*AE53 -> 21147536
B54: Done | C54: USM | D54: SC-USM-290623 | E54: SC-USM-290623 | F54: 45106 | G54: USM | H54: STOCK | L54: 100% BEFORE PICK UP | M54: FCA | O54: FURNITURE | P54: Cabinet | R54: USMUS00220 | S54: USMUS00220 | T54: Tủ nội thất văn phòng USM HALLER, USMUS00220, kích thước (dài 1523 x rộng 373 x cao 740 mm), bằng Kim loại, màu Be (USM Beige). Hiệu USM | U54: 1 | V54: EUR | X54: =W54*U54 -> 0 | Z54: 767.53 | AB54: =IF(AA54="F.O.C", 0, Z54*U54) -> 767.53 | AC54: =Z54*U54 -> 767.53 | AE54: 25590.88 | AF54: 0.1 | AG54: =(AC54*AE54+BO54+BP54+BQ54+BS54)*AF54 -> 2019572.4 | AI54: =(AC54*AE54+AG54+BF54+BG54+BH54+BJ54)*AH54 -> 0 | AJ54: 102082282 | AK54: 13/07/2023 | AO54: SEA | AQ54: 03/08/2023 | AV54: 105728943720 | AW54: 45189 | AX54: 20/09/2023 | BA54: Xong | BB54: BÌNH PHÚ | BC54: 45195 | BD54: Lô 5 | BE54: {=IF(BD54="","",AC54/SUMPRODUCT(--(BD54=$BD$4:$BD$12824),$AC$4:$AC$12824))} -> 0.0088545866 | BO54: =VLOOKUP(BD54,$BD$4:$BN$12824,3,0)*BE54 -> 534755.05 | BR54: =VLOOKUP(BD54,$BD$4:$BN$12824,6,0)*BE54 -> 36339.223 | BS54: =VLOOKUP(BD54,$BD$4:$BN$12824,7,0)*BE54 -> 19200.534 | BU54: =VLOOKUP(BD54,$BD$4:$BN$12824,9,0)*BE54 -> 4427.2933 | BW54: =VLOOKUP(BD54,$BD$4:$BN$12824,11,0)*BE54 -> 0 | BX54: =SUM(BO54:BW54) -> 594722.1 | BY54: =(AB54*AE54+AG54+BX54)/U54 -> 22256063 | BZ54: =BY54*U54 -> 22256063 | CA54: =_xlfn.MAXIFS($BY$4:$BY$12824,$S$4:$S$12824,$S54) -> 25848825 | CF54: =AC54*AE54 -> 19641768
B55: Done | C55: USM | D55: SC-USM-290623 | E55: SC-USM-290623 | F55: 45106 | G55: USM | H55: STOCK | L55: 100% BEFORE PICK UP | M55: FCA | O55: FURNITURE | P55: Cabinet | R55: USMUS00311 | S55: USMUS00311 | T55: Bàn văn phòng USM HALLER, USMUS00311, kích thước (dài 1750 x rộng 750 x cao 740 mm), Mặt Fenix, khung Kim loại, màu Trắng (Bianco Kos). Hiệu USM | U55: 6 | V55: EUR | X55: =W55*U55 -> 0 | Z55: 605.08 | AB55: =IF(AA55="F.O.C", 0, Z55*U55) -> 3630.48 | AC55: =Z55*U55 -> 3630.48 | AE55: 25590.88 | AF55: 0.1 | AG55: =(AC55*AE55+BO55+BP55+BQ55+BS55)*AF55 -> 9552743.3 | AI55: =(AC55*AE55+AG55+BF55+BG55+BH55+BJ55)*AH55 -> 0 | AJ55: 102082282 | AK55: 13/07/2023 | AO55: SEA | AQ55: 03/08/2023 | AV55: 105728943720 | AW55: 45189 | AX55: 20/09/2023 | BA55: Xong | BB55: BÌNH PHÚ | BC55: 45195 | BD55: Lô 5 | BE55: {=IF(BD55="","",AC55/SUMPRODUCT(--(BD55=$BD$4:$BD$12824),$AC$4:$AC$12824))} -> 0.041882923 | BO55: =VLOOKUP(BD55,$BD$4:$BN$12824,3,0)*BE55 -> 2529435.3 | BR55: =VLOOKUP(BD55,$BD$4:$BN$12824,6,0)*BE55 -> 171887.51 | BS55: =VLOOKUP(BD55,$BD$4:$BN$12824,7,0)*BE55 -> 90820.102 | BU55: =VLOOKUP(BD55,$BD$4:$BN$12824,9,0)*BE55 -> 20941.461 | BW55: =VLOOKUP(BD55,$BD$4:$BN$12824,11,0)*BE55 -> 0 | BX55: =SUM(BO55:BW55) -> 2813084.4 | BY55: =(AB55*AE55+AG55+BX55)/U55 -> 17545501 | BZ55: =BY55*U55 -> 1.0527301e+08 | CA55: =_xlfn.MAXIFS($BY$4:$BY$12824,$S$4:$S$12824,$S55) -> 17545501 | CF55: =AC55*AE55 -> 92907178
B56: Done | C56: USM | D56: SC-USM-290623 | E56: SC-USM-290623 | F56: 45106 | G56: USM | H56: STOCK | L56: 100% BEFORE PICK UP | M56: FCA | O56: FURNITURE | P56: Cabinet | R56: USMUS10013 | S56: USMUS10013 | T56: Tủ nội thất văn phòng USM HALLER, USMUS10013, kích thước (dài 3063 x rộng 373 x cao 2490 mm), bằng Kim loại, màu Xanh Gentian (Gentian Blue). Hiệu USM | U56: 1 | V56: EUR | X56: =W56*U56 -> 0 | Z56: 2234.88 | AB56: =IF(AA56="F.O.C", 0, Z56*U56) -> 2234.88 | AC56: =Z56*U56 -> 2234.88 | AE56: 25590.88 | AF56: 0.1 | AG56: =(AC56*AE56+BO56+BP56+BQ56+BS56)*AF56 -> 5880554.4 | AI56: =(AC56*AE56+AG56+BF56+BG56+BH56+BJ56)*AH56 -> 0 | AJ56: 102082282 | AK56: 13/07/2023 | AO56: SEA | AQ56: 03/08/2023 | AV56: 105728943720 | AW56: 45189 | AX56: 20/09/2023 | BA56: Xong | BB56: BÌNH PHÚ | BC56: 45195 | BD56: Lô 5 | BE56: {=IF(BD56="","",AC56/SUMPRODUCT(--(BD56=$BD$4:$BD$12824),$AC$4:$AC$12824))} -> 0.025782625 | BO56: =VLOOKUP(BD56,$BD$4:$BN$12824,3,0)*BE56 -> 1557090.1 | BR56: =VLOOKUP(BD56,$BD$4:$BN$12824,6,0)*BE56 -> 105811.89 | BS56: =VLOOKUP(BD56,$BD$4:$BN$12824,7,0)*BE56 -> 55907.767 | BU56: =VLOOKUP(BD56,$BD$4:$BN$12824,9,0)*BE56 -> 12891.313 | BW56: =VLOOKUP(BD56,$BD$4:$BN$12824,11,0)*BE56 -> 0 | BX56: =SUM(BO56:BW56) -> 1731701.1 | BY56: =(AB56*AE56+AG56+BX56)/U56 -> 64804801 | BZ56: =BY56*U56 -> 64804801 | CA56: =_xlfn.MAXIFS($BY$4:$BY$12824,$S$4:$S$12824,$S56) -> 64804801 | CF56: =AC56*AE56 -> 57192546
B57: Done | C57: USM | D57: SC-USM-290623 | E57: SC-USM-290623 | F57: 45106 | G57: USM | H57: STOCK | L57: 100% BEFORE PICK UP | M57: FCA | O57: FURNITURE | P57: Cabinet | R57: USMUS10014 | S57: USMUS10014 | T57: Tủ nội thất văn phòng USM HALLER, USMUS10014, kích thước (dài 2523 x rộng 373 x cao 2140 mm), bằng Kim loại, màu Xám (USM Mid-Gray). Hiệu USM | U57: 1 | V57: EUR | X57: =W57*U57 -> 0 | Z57: 1556.33 | AB57: =IF(AA57="F.O.C", 0, Z57*U57) -> 1556.33 | AC57: =Z57*U57 -> 1556.33 | AE57: 25590.88 | AF57: 0.1 | AG57: =(AC57*AE57+BO57+BP57+BQ57+BS57)*AF57 -> 4095111.7 | AI57: =(AC57*AE57+AG57+BF57+BG57+BH57+BJ57)*AH57 -> 0 | AJ57: 102082282 | AK57: 13/07/2023 | AO57: SEA | AQ57: 03/08/2023 | AV57: 105728943720 | AW57: 45189 | AX57: 20/09/2023 | BA57: Xong | BB57: BÌNH PHÚ | BC57: 45195 | BD57: Lô 5 | BE57: {=IF(BD57="","",AC57/SUMPRODUCT(--(BD57=$BD$4:$BD$12824),$AC$4:$AC$12824))} -> 0.017954554 | BO57: =VLOOKUP(BD57,$BD$4:$BN$12824,3,0)*BE57 -> 1084329.4 | BR57: =VLOOKUP(BD57,$BD$4:$BN$12824,6,0)*BE57 -> 73685.489 | BS57: =VLOOKUP(BD57,$BD$4:$BN$12824,7,0)*BE57 -> 38933.157 | BU57: =VLOOKUP(BD57,$BD$4:$BN$12824,9,0)*BE57 -> 8977.277 | BW57: =VLOOKUP(BD57,$BD$4:$BN$12824,11,0)*BE57 -> 0 | BX57: =SUM(BO57:BW57) -> 1205925.3 | BY57: =(AB57*AE57+AG57+BX57)/U57 -> 45128891 | BZ57: =BY57*U57 -> 45128891 | CA57: =_xlfn.MAXIFS($BY$4:$BY$12824,$S$4:$S$12824,$S57) -> 45128891 | CF57: =AC57*AE57 -> 39827854
B58: Done | C58: USM | D58: SC-USM-290623 | E58: SC-USM-290623 | F58: 45106 | G58: USM | H58: STOCK | L58: 100% BEFORE PICK UP | M58: FCA | O58: FURNITURE | P58: Cabinet | R58: USMUS10001 | S58: USMUS10001 | T58: Kệ nội thất văn phòng USM HALLER, USMUS10001, kích thước (dài 5523 x rộng 1073 x cao 2040 mm), bằng Kim loại, màu Cam (Pure Orange). Hiệu USM | U58: 1 | V58: EUR | X58: =W58*U58 -> 0 | Z58: 4889.76 | AB58: =IF(AA58="F.O.C", 0, Z58*U58) -> 4889.76 | AC58: =Z58*U58 -> 4889.76 | AE58: 25590.88 | AF58: 0.1 | AG58: =(AC58*AE58+BO58+BP58+BQ58+BS58)*AF58 -> 12866239 | AI58: =(AC58*AE58+AG58+BF58+BG58+BH58+BJ58)*AH58 -> 0 | AJ58: 102082282 | AK58: 13/07/2023 | AO58: SEA | AQ58: 03/08/2023 | AV58: 105728943720 | AW58: 45189 | AX58: 20/09/2023 | BA58: Xong | BB58: BÌNH PHÚ | BC58: 45195 | BD58: Lô 5 | BE58: {=IF(BD58="","",AC58/SUMPRODUCT(--(BD58=$BD$4:$BD$12824),$AC$4:$AC$12824))} -> 0.056410568 | BO58: =VLOOKUP(BD58,$BD$4:$BN$12824,3,0)*BE58 -> 3406803.4 | BR58: =VLOOKUP(BD58,$BD$4:$BN$12824,6,0)*BE58 -> 231508.97 | BS58: =VLOOKUP(BD58,$BD$4:$BN$12824,7,0)*BE58 -> 122322.26 | BU58: =VLOOKUP(BD58,$BD$4:$BN$12824,9,0)*BE58 -> 28205.284 | BW58: =VLOOKUP(BD58,$BD$4:$BN$12824,11,0)*BE58 -> 0 | BX58: =SUM(BO58:BW58) -> 3788840 | BY58: =(AB58*AE58+AG58+BX58)/U58 -> 1.4178834e+08 | BZ58: =BY58*U58 -> 1.4178834e+08 | CA58: =_xlfn.MAXIFS($BY$4:$BY$12824,$S$4:$S$12824,$S58) -> 1.4178834e+08 | CF58: =AC58*AE58 -> 1.2513326e+08
...

Sheet Cost
B1: THÔNG TIN CHUNG | H1: BẢO HIỂM | L1: THUẾ | O1: VẬN CHUYỂN | Z1: KHAI HẢI QUAN VÀ CÁC PHI PHÍ LIÊN QUAN
B2: Hãng | C2: Số Bill | D2: SC | E2: Invoice | F2: Số lô | H2: Bảo hiểm (chưa VAT) =Total/1.1 (10%) | J2: Thanh toán | L2: Thuế NK | M2: Thuế VAT | O2: FWD | P2: EXW+OF | R2: Local charge (include VAT) | T2: Lưu kho (include VAT) | V2: Trucking nội địa (include VAT) | X2: Thanh toán | Z2: Phí Dịch vụ khai Hải quan (+VAT) | AB2: Lệ phí hải quan | AC2: Phí sử dụng cơ sở hạ tầng (SEA) | AE2: Phí dịch vụ chi ngoài (+VAT) | AG2: Phí dịch vụ bốc dỡ (AIR) (+VAT) | AI2: Chuyển bãi nội bộ (SEA) (+VAT) | AK2: Phí rút đóng kiểm hóa (SEA) (+VAT) | AM2: Phí nâng cont | AO2: Phí hạ rỗng | AQ2: Thanh toán | AS2: THỬ NGHIỆM | AV2: Thông báo nhập kho
I3: Cost 3 | Q3: Cost 1 | S3: Cost 2 | U3: Cost 2 | W3: Cost 2 | AA3: Cost 5 | AB3: Cost 4 | AD3: Cost 4 | AF3: Cost 5 | AH3: Cost 5 | AJ3: Cost 5 | AL3: Cost 5 | AN3: Cost 5 | AP3: Cost 5 | AT3: Cost 6
H4: HĐ | I4: Số tiền | P4: HĐ | Q4: Số tiền | R4: HĐ | S4: Số tiền | T4: HĐ | U4: Số tiền | V4: HĐ | W4: Số tiền | Z4: HĐ | AA4: Số tiền | AC4: HĐ | AD4: Số tiền | AE4: HĐ | AF4: Số tiền | AG4: HĐ | AH4: Số tiền | AI4: HĐ | AJ4: Số tiền | AK4: HĐ | AL4: Số tiền | AM4: HĐ | AN4: Số tiền | AO4: HĐ | AP4: Số tiền | AS4: HĐ | AT4: Số tiền
B5: Santa&Cole | C5: 250401582/0111 | D5: SC-S&C-01-281224-DH-SHOWROOM | E5: SC-S&C-01-281224-DH-SHOWROOM | F5: Lô 68 | H5: 4963 | I5: 546197 | J5: Đã TT | L5: 47492627 | M5: 47492627 | O5: Bách Việt | P5: 17199 | Q5: 11967068 | R5: 18465 | S5: =7161281-W5 -> 4461281 | T5: no | U5: 0 | V5: 18465 | W5: 2700000 | X5: Đã TT | Z5: 1853 | AA5: 648000 | AB5: 20000 | AC5: 1350202 | AD5: 3585 | AE5: no | AF5: 0 | AG5: no | AH5: 0 | AI5: no | AJ5: 0 | AK5: no | AL5: 0 | AM5: no | AN5: 0 | AO5: no | AP5: 0 | AQ5: Đã TT | AV5: Rồi
B6: Vitra | C6: FRA-00011902 | D6: NNH-VT-2025-002-1906-RIMOWA | E6: 5085293 | F6: Lô 69 | H6: no | I6: 0 | J6: / | L6: 0 | M6: 10584585 | O6: Bách Việt | P6: 18908 | Q6: 16471563 | R6: 19546 | S6: =1774947-W6 -> 1133427 | T6: 234093 bach viet+'231456 dynamic (lưu kho +phục vụ hàng nhập) | U6: =656003+1245548 -> 1901551 | V6: 19546 | W6: =594000*1.08 -> 641520 | X6: Đã TT | Z6: 1995 | AA6: 1188000 | AB6: 20000 | AC6: no | AD6: 0 | AE6: no | AF6: 0 | AG6: no | AH6: 0 | AI6: no | AJ6: 0 | AK6: no | AL6: 0 | AM6: no | AN6: 0 | AO6: no | AP6: 0 | AQ6: Đã TT | AV6: Rồi
